*** Starting uWSGI 2.0.21 (64bit) on [Tue Jul  4 15:45:38 2023] ***
compiled with version: Apple LLVM 14.0.3 (clang-1403.0.22.14.1) on 04 July 2023 07:43:37
os: Darwin-22.5.0 Darwin Kernel Version 22.5.0: Thu Jun  8 22:22:22 PDT 2023; root:xnu-8796.121.3~7/RELEASE_X86_64
nodename: lvjingdeMacBook-Pro.local
machine: x86_64
clock source: unix
pcre jit disabled
detected number of CPU cores: 12
current working directory: /Users/lvjing/sorcery-management-platform/backend
writing pidfile to uwsgi.pid
detected binary path: /usr/local/var/pyenv/versions/3.9.0/envs/venv3.9.0/bin/uwsgi
chdir() to /Users/lvjing/sorcery-management-platform/backend
your processes number limit is 2784
your memory page size is 4096 bytes
detected max file descriptor number: 10240
lock engine: OSX spinlocks
thunder lock: disabled (you can enable it with --thunder-lock)
uWSGI http bound on 0.0.0.0:8000 fd 4
uwsgi socket 0 bound to TCP address 127.0.0.1:64093 (port auto-assigned) fd 3
Python version: 3.9.0 (default, Jun  6 2023, 10:09:24)  [Clang 14.0.3 (clang-1403.0.22.14.1)]
Python main interpreter initialized at 0x7fbf54906f90
python threads support enabled
your server socket listen backlog is limited to 100 connections
your mercy for graceful operations on workers is 60 seconds
mapped 416640 bytes (406 KB) for 8 cores
*** Operational MODE: preforking+threaded ***
WSGI app 0 (mountpoint='') ready in 1 seconds on interpreter 0x7fbf54906f90 pid: 85316 (default app)
*** uWSGI is running in multiple interpreter mode ***
spawned uWSGI master process (pid: 85316)
spawned uWSGI worker 1 (pid: 85341, cores: 2)
spawned uWSGI worker 2 (pid: 85342, cores: 2)
spawned uWSGI worker 3 (pid: 85343, cores: 2)
spawned uWSGI worker 4 (pid: 85344, cores: 2)
spawned uWSGI http 1 (pid: 85345)
[pid: 85344|app: 0|req: 1/1] 127.0.0.1 () {60 vars in 1268 bytes} [Tue Jul  4 07:46:37 2023] GET /api/users/info => generated 118 bytes in 881 msecs (HTTP/1.1 200) 7 headers in 228 bytes (1 switches on core 0)
[pid: 85344|app: 0|req: 2/2] 127.0.0.1 () {66 vars in 1407 bytes} [Tue Jul  4 07:46:44 2023] POST /api/projects/list?page=1&size=6 => generated 1240 bytes in 33 msecs (HTTP/1.1 200) 6 headers in 215 bytes (2 switches on core 1)
WARNING Not Found: /static/images/105131d433a807eb1c778be9c93286f1.png
WARNING Not Found: /static/images/04877dc43746a4e2498ece93540c48aa.png
[pid: 85344|app: 0|req: 4/4] 127.0.0.1 () {60 vars in 1368 bytes} [Tue Jul  4 07:46:44 2023] GET /static/images/105131d433a807eb1c778be9c93286f1.png => generated 2332 bytes in 19 msecs (HTTP/1.1 404) 6 headers in 215 bytes (2 switches on core 1)
[pid: 85344|app: 0|req: 4/4] 127.0.0.1 () {60 vars in 1368 bytes} [Tue Jul  4 07:46:44 2023] GET /static/images/04877dc43746a4e2498ece93540c48aa.png => generated 2332 bytes in 21 msecs (HTTP/1.1 404) 6 headers in 215 bytes (2 switches on core 0)
[pid: 85344|app: 0|req: 5/5] 127.0.0.1 () {60 vars in 1268 bytes} [Tue Jul  4 07:46:47 2023] GET /api/users/info => generated 118 bytes in 27 msecs (HTTP/1.1 200) 7 headers in 228 bytes (2 switches on core 1)
[pid: 85344|app: 0|req: 6/6] 127.0.0.1 () {66 vars in 1407 bytes} [Tue Jul  4 07:46:47 2023] POST /api/projects/list?page=1&size=6 => generated 1240 bytes in 33 msecs (HTTP/1.1 200) 6 headers in 215 bytes (1 switches on core 0)
WARNING Not Found: /static/images/04877dc43746a4e2498ece93540c48aa.png
[pid: 85344|app: 0|req: 8/7] 127.0.0.1 () {58 vars in 1313 bytes} [Tue Jul  4 07:46:47 2023] GET /static/images/04877dc43746a4e2498ece93540c48aa.png => generated 2332 bytes in 11 msecs (HTTP/1.1 404) 6 headers in 215 bytes (1 switches on core 0)
WARNING Not Found: /static/images/105131d433a807eb1c778be9c93286f1.png
[pid: 85344|app: 0|req: 8/8] 127.0.0.1 () {58 vars in 1313 bytes} [Tue Jul  4 07:46:47 2023] GET /static/images/105131d433a807eb1c778be9c93286f1.png => generated 2332 bytes in 13 msecs (HTTP/1.1 404) 6 headers in 215 bytes (2 switches on core 1)
[pid: 85343|app: 0|req: 1/9] 127.0.0.1 () {66 vars in 1392 bytes} [Tue Jul  4 07:46:50 2023] POST /api/projects/list?page=1&size=10 => generated 1241 bytes in 781 msecs (HTTP/1.1 200) 6 headers in 215 bytes (1 switches on core 1)
[pid: 85344|app: 0|req: 9/10] 127.0.0.1 () {60 vars in 1297 bytes} [Tue Jul  4 07:46:51 2023] GET /api/modules/tree?project_id=1 => generated 140 bytes in 25 msecs (HTTP/1.1 200) 6 headers in 214 bytes (1 switches on core 0)
[pid: 85344|app: 0|req: 11/11] 127.0.0.1 () {60 vars in 1280 bytes} [Tue Jul  4 07:46:52 2023] GET /api/modules/all/tree => generated 300 bytes in 37 msecs (HTTP/1.1 200) 6 headers in 214 bytes (2 switches on core 0)
[pid: 85344|app: 0|req: 11/12] 127.0.0.1 () {66 vars in 1403 bytes} [Tue Jul  4 07:46:52 2023] POST /api/cases/list?page=1&size=10 => generated 98 bytes in 61 msecs (HTTP/1.1 200) 6 headers in 213 bytes (1 switches on core 1)
[pid: 85343|app: 0|req: 2/13] 127.0.0.1 () {60 vars in 1280 bytes} [Tue Jul  4 07:46:54 2023] GET /api/cases/suite/tree => generated 69 bytes in 38 msecs (HTTP/1.1 200) 6 headers in 213 bytes (2 switches on core 1)
[pid: 85344|app: 0|req: 12/14] 127.0.0.1 () {60 vars in 1280 bytes} [Tue Jul  4 07:46:59 2023] GET /api/cases/suite/tree => generated 69 bytes in 22 msecs (HTTP/1.1 200) 6 headers in 213 bytes (2 switches on core 0)
[pid: 85344|app: 0|req: 13/15] 127.0.0.1 () {60 vars in 1284 bytes} [Tue Jul  4 07:47:02 2023] GET /api/info/har-file-list => generated 187 bytes in 16 msecs (HTTP/1.1 200) 6 headers in 214 bytes (1 switches on core 1)
[pid: 85344|app: 0|req: 14/16] 127.0.0.1 () {66 vars in 1407 bytes} [Tue Jul  4 07:55:00 2023] POST /api/projects/list?page=1&size=6 => generated 1240 bytes in 33 msecs (HTTP/1.1 200) 6 headers in 215 bytes (2 switches on core 0)
WARNING Not Found: /static/images/105131d433a807eb1c778be9c93286f1.png
[pid: 85344|app: 0|req: 15/17] 127.0.0.1 () {58 vars in 1313 bytes} [Tue Jul  4 07:55:00 2023] GET /static/images/105131d433a807eb1c778be9c93286f1.png => generated 2332 bytes in 7 msecs (HTTP/1.1 404) 6 headers in 215 bytes (1 switches on core 1)
Traceback (most recent call last):
  File "/usr/local/var/pyenv/versions/3.9.0/envs/venv3.9.0/lib/python3.9/site-packages/django/core/handlers/exception.py", line 55, in inner
    response = get_response(request)
  File "/usr/local/var/pyenv/versions/3.9.0/envs/venv3.9.0/lib/python3.9/site-packages/django/core/handlers/base.py", line 181, in _get_response
    callback, callback_args, callback_kwargs = self.resolve_request(request)
  File "/usr/local/var/pyenv/versions/3.9.0/envs/venv3.9.0/lib/python3.9/site-packages/django/core/handlers/base.py", line 313, in resolve_request
    resolver_match = resolver.resolve(request.path_info)
  File "/usr/local/var/pyenv/versions/3.9.0/envs/venv3.9.0/lib/python3.9/site-packages/django/urls/resolvers.py", line 663, in resolve
    for pattern in self.url_patterns:
  File "/usr/local/var/pyenv/versions/3.9.0/envs/venv3.9.0/lib/python3.9/site-packages/django/utils/functional.py", line 57, in __get__
    res = instance.__dict__[self.name] = self.func(instance)
  File "/usr/local/var/pyenv/versions/3.9.0/envs/venv3.9.0/lib/python3.9/site-packages/django/urls/resolvers.py", line 715, in url_patterns
    patterns = getattr(self.urlconf_module, "urlpatterns", self.urlconf_module)
  File "/usr/local/var/pyenv/versions/3.9.0/envs/venv3.9.0/lib/python3.9/site-packages/django/utils/functional.py", line 57, in __get__
    res = instance.__dict__[self.name] = self.func(instance)
  File "/usr/local/var/pyenv/versions/3.9.0/envs/venv3.9.0/lib/python3.9/site-packages/django/urls/resolvers.py", line 708, in urlconf_module
    return import_module(self.urlconf_name)
  File "/usr/local/var/pyenv/versions/3.9.0/lib/python3.9/importlib/__init__.py", line 127, in import_module
    return _bootstrap._gcd_import(name[level:], package, level)
  File "<frozen importlib._bootstrap>", line 1030, in _gcd_import
  File "<frozen importlib._bootstrap>", line 1007, in _find_and_load
  File "<frozen importlib._bootstrap>", line 986, in _find_and_load_unlocked
  File "<frozen importlib._bootstrap>", line 680, in _load_unlocked
  File "<frozen importlib._bootstrap_external>", line 790, in exec_module
  File "<frozen importlib._bootstrap>", line 228, in _call_with_frames_removed
  File "./backend/urls.py", line 17, in <module>
    from django.conf.static import serve
ModuleNotFoundError: No module named 'django.conf.static'

During handling of the above exception, another exception occurred:

Traceback (most recent call last):
  File "/usr/local/var/pyenv/versions/3.9.0/envs/venv3.9.0/lib/python3.9/site-packages/django/core/handlers/exception.py", line 55, in inner
    response = get_response(request)
  File "/usr/local/var/pyenv/versions/3.9.0/envs/venv3.9.0/lib/python3.9/site-packages/django/utils/deprecation.py", line 134, in __call__
    response = response or self.get_response(request)
  File "/usr/local/var/pyenv/versions/3.9.0/envs/venv3.9.0/lib/python3.9/site-packages/django/core/handlers/exception.py", line 57, in inner
    response = response_for_exception(request, exc)
  File "/usr/local/var/pyenv/versions/3.9.0/envs/venv3.9.0/lib/python3.9/site-packages/django/core/handlers/exception.py", line 140, in response_for_exception
    response = handle_uncaught_exception(
  File "/usr/local/var/pyenv/versions/3.9.0/envs/venv3.9.0/lib/python3.9/site-packages/django/core/handlers/exception.py", line 181, in handle_uncaught_exception
    return debug.technical_500_response(request, *exc_info)
  File "/usr/local/var/pyenv/versions/3.9.0/envs/venv3.9.0/lib/python3.9/site-packages/django/views/debug.py", line 67, in technical_500_response
    html = reporter.get_traceback_html()
  File "/usr/local/var/pyenv/versions/3.9.0/envs/venv3.9.0/lib/python3.9/site-packages/django/views/debug.py", line 410, in get_traceback_html
    c = Context(self.get_traceback_data(), use_l10n=False)
  File "/usr/local/var/pyenv/versions/3.9.0/envs/venv3.9.0/lib/python3.9/site-packages/django/views/debug.py", line 393, in get_traceback_data
    c["raising_view_name"] = get_caller(self.request)
  File "/usr/local/var/pyenv/versions/3.9.0/envs/venv3.9.0/lib/python3.9/site-packages/django/views/debug.py", line 100, in get_caller
    resolver_match = resolve(request.path)
  File "/usr/local/var/pyenv/versions/3.9.0/envs/venv3.9.0/lib/python3.9/site-packages/django/urls/base.py", line 24, in resolve
    return get_resolver(urlconf).resolve(path)
  File "/usr/local/var/pyenv/versions/3.9.0/envs/venv3.9.0/lib/python3.9/site-packages/django/urls/resolvers.py", line 663, in resolve
    for pattern in self.url_patterns:
  File "/usr/local/var/pyenv/versions/3.9.0/envs/venv3.9.0/lib/python3.9/site-packages/django/utils/functional.py", line 57, in __get__
    res = instance.__dict__[self.name] = self.func(instance)
  File "/usr/local/var/pyenv/versions/3.9.0/envs/venv3.9.0/lib/python3.9/site-packages/django/urls/resolvers.py", line 715, in url_patterns
    patterns = getattr(self.urlconf_module, "urlpatterns", self.urlconf_module)
  File "/usr/local/var/pyenv/versions/3.9.0/envs/venv3.9.0/lib/python3.9/site-packages/django/utils/functional.py", line 57, in __get__
    res = instance.__dict__[self.name] = self.func(instance)
  File "/usr/local/var/pyenv/versions/3.9.0/envs/venv3.9.0/lib/python3.9/site-packages/django/urls/resolvers.py", line 708, in urlconf_module
    return import_module(self.urlconf_name)
  File "/usr/local/var/pyenv/versions/3.9.0/lib/python3.9/importlib/__init__.py", line 127, in import_module
    return _bootstrap._gcd_import(name[level:], package, level)
  File "<frozen importlib._bootstrap>", line 1030, in _gcd_import
  File "<frozen importlib._bootstrap>", line 1007, in _find_and_load
  File "<frozen importlib._bootstrap>", line 986, in _find_and_load_unlocked
  File "<frozen importlib._bootstrap>", line 680, in _load_unlocked
  File "<frozen importlib._bootstrap_external>", line 790, in exec_module
  File "<frozen importlib._bootstrap>", line 228, in _call_with_frames_removed
  File "./backend/urls.py", line 17, in <module>
    from django.conf.static import serve
ModuleNotFoundError: No module named 'django.conf.static'

During handling of the above exception, another exception occurred:

Traceback (most recent call last):
  File "/usr/local/var/pyenv/versions/3.9.0/envs/venv3.9.0/lib/python3.9/site-packages/django/core/handlers/exception.py", line 55, in inner
    response = get_response(request)
  File "/usr/local/var/pyenv/versions/3.9.0/envs/venv3.9.0/lib/python3.9/site-packages/django/utils/deprecation.py", line 134, in __call__
    response = response or self.get_response(request)
  File "/usr/local/var/pyenv/versions/3.9.0/envs/venv3.9.0/lib/python3.9/site-packages/django/core/handlers/exception.py", line 57, in inner
    response = response_for_exception(request, exc)
  File "/usr/local/var/pyenv/versions/3.9.0/envs/venv3.9.0/lib/python3.9/site-packages/django/core/handlers/exception.py", line 140, in response_for_exception
    response = handle_uncaught_exception(
  File "/usr/local/var/pyenv/versions/3.9.0/envs/venv3.9.0/lib/python3.9/site-packages/django/core/handlers/exception.py", line 181, in handle_uncaught_exception
    return debug.technical_500_response(request, *exc_info)
  File "/usr/local/var/pyenv/versions/3.9.0/envs/venv3.9.0/lib/python3.9/site-packages/django/views/debug.py", line 67, in technical_500_response
    html = reporter.get_traceback_html()
  File "/usr/local/var/pyenv/versions/3.9.0/envs/venv3.9.0/lib/python3.9/site-packages/django/views/debug.py", line 410, in get_traceback_html
    c = Context(self.get_traceback_data(), use_l10n=False)
  File "/usr/local/var/pyenv/versions/3.9.0/envs/venv3.9.0/lib/python3.9/site-packages/django/views/debug.py", line 393, in get_traceback_data
    c["raising_view_name"] = get_caller(self.request)
  File "/usr/local/var/pyenv/versions/3.9.0/envs/venv3.9.0/lib/python3.9/site-packages/django/views/debug.py", line 100, in get_caller
    resolver_match = resolve(request.path)
  File "/usr/local/var/pyenv/versions/3.9.0/envs/venv3.9.0/lib/python3.9/site-packages/django/urls/base.py", line 24, in resolve
    return get_resolver(urlconf).resolve(path)
  File "/usr/local/var/pyenv/versions/3.9.0/envs/venv3.9.0/lib/python3.9/site-packages/django/urls/resolvers.py", line 663, in resolve
    for pattern in self.url_patterns:
  File "/usr/local/var/pyenv/versions/3.9.0/envs/venv3.9.0/lib/python3.9/site-packages/django/utils/functional.py", line 57, in __get__
    res = instance.__dict__[self.name] = self.func(instance)
  File "/usr/local/var/pyenv/versions/3.9.0/envs/venv3.9.0/lib/python3.9/site-packages/django/urls/resolvers.py", line 715, in url_patterns
    patterns = getattr(self.urlconf_module, "urlpatterns", self.urlconf_module)
  File "/usr/local/var/pyenv/versions/3.9.0/envs/venv3.9.0/lib/python3.9/site-packages/django/utils/functional.py", line 57, in __get__
    res = instance.__dict__[self.name] = self.func(instance)
  File "/usr/local/var/pyenv/versions/3.9.0/envs/venv3.9.0/lib/python3.9/site-packages/django/urls/resolvers.py", line 708, in urlconf_module
    return import_module(self.urlconf_name)
  File "/usr/local/var/pyenv/versions/3.9.0/lib/python3.9/importlib/__init__.py", line 127, in import_module
    return _bootstrap._gcd_import(name[level:], package, level)
  File "<frozen importlib._bootstrap>", line 1030, in _gcd_import
  File "<frozen importlib._bootstrap>", line 1007, in _find_and_load
  File "<frozen importlib._bootstrap>", line 986, in _find_and_load_unlocked
  File "<frozen importlib._bootstrap>", line 680, in _load_unlocked
  File "<frozen importlib._bootstrap_external>", line 790, in exec_module
  File "<frozen importlib._bootstrap>", line 228, in _call_with_frames_removed
  File "./backend/urls.py", line 17, in <module>
    from django.conf.static import serve
ModuleNotFoundError: No module named 'django.conf.static'

During handling of the above exception, another exception occurred:

Traceback (most recent call last):
  File "/usr/local/var/pyenv/versions/3.9.0/envs/venv3.9.0/lib/python3.9/site-packages/django/core/handlers/exception.py", line 55, in inner
    response = get_response(request)
  File "/usr/local/var/pyenv/versions/3.9.0/envs/venv3.9.0/lib/python3.9/site-packages/django/utils/deprecation.py", line 134, in __call__
    response = response or self.get_response(request)
  File "/usr/local/var/pyenv/versions/3.9.0/envs/venv3.9.0/lib/python3.9/site-packages/django/core/handlers/exception.py", line 57, in inner
    response = response_for_exception(request, exc)
  File "/usr/local/var/pyenv/versions/3.9.0/envs/venv3.9.0/lib/python3.9/site-packages/django/core/handlers/exception.py", line 140, in response_for_exception
    response = handle_uncaught_exception(
  File "/usr/local/var/pyenv/versions/3.9.0/envs/venv3.9.0/lib/python3.9/site-packages/django/core/handlers/exception.py", line 181, in handle_uncaught_exception
    return debug.technical_500_response(request, *exc_info)
  File "/usr/local/var/pyenv/versions/3.9.0/envs/venv3.9.0/lib/python3.9/site-packages/django/views/debug.py", line 67, in technical_500_response
    html = reporter.get_traceback_html()
  File "/usr/local/var/pyenv/versions/3.9.0/envs/venv3.9.0/lib/python3.9/site-packages/django/views/debug.py", line 410, in get_traceback_html
    c = Context(self.get_traceback_data(), use_l10n=False)
  File "/usr/local/var/pyenv/versions/3.9.0/envs/venv3.9.0/lib/python3.9/site-packages/django/views/debug.py", line 393, in get_traceback_data
    c["raising_view_name"] = get_caller(self.request)
  File "/usr/local/var/pyenv/versions/3.9.0/envs/venv3.9.0/lib/python3.9/site-packages/django/views/debug.py", line 100, in get_caller
    resolver_match = resolve(request.path)
  File "/usr/local/var/pyenv/versions/3.9.0/envs/venv3.9.0/lib/python3.9/site-packages/django/urls/base.py", line 24, in resolve
    return get_resolver(urlconf).resolve(path)
  File "/usr/local/var/pyenv/versions/3.9.0/envs/venv3.9.0/lib/python3.9/site-packages/django/urls/resolvers.py", line 663, in resolve
    for pattern in self.url_patterns:
  File "/usr/local/var/pyenv/versions/3.9.0/envs/venv3.9.0/lib/python3.9/site-packages/django/utils/functional.py", line 57, in __get__
    res = instance.__dict__[self.name] = self.func(instance)
  File "/usr/local/var/pyenv/versions/3.9.0/envs/venv3.9.0/lib/python3.9/site-packages/django/urls/resolvers.py", line 715, in url_patterns
    patterns = getattr(self.urlconf_module, "urlpatterns", self.urlconf_module)
  File "/usr/local/var/pyenv/versions/3.9.0/envs/venv3.9.0/lib/python3.9/site-packages/django/utils/functional.py", line 57, in __get__
    res = instance.__dict__[self.name] = self.func(instance)
  File "/usr/local/var/pyenv/versions/3.9.0/envs/venv3.9.0/lib/python3.9/site-packages/django/urls/resolvers.py", line 708, in urlconf_module
    return import_module(self.urlconf_name)
  File "/usr/local/var/pyenv/versions/3.9.0/lib/python3.9/importlib/__init__.py", line 127, in import_module
    return _bootstrap._gcd_import(name[level:], package, level)
  File "<frozen importlib._bootstrap>", line 1030, in _gcd_import
  File "<frozen importlib._bootstrap>", line 1007, in _find_and_load
  File "<frozen importlib._bootstrap>", line 986, in _find_and_load_unlocked
  File "<frozen importlib._bootstrap>", line 680, in _load_unlocked
  File "<frozen importlib._bootstrap_external>", line 790, in exec_module
  File "<frozen importlib._bootstrap>", line 228, in _call_with_frames_removed
  File "./backend/urls.py", line 17, in <module>
    from django.conf.static import serve
ModuleNotFoundError: No module named 'django.conf.static'

During handling of the above exception, another exception occurred:

Traceback (most recent call last):
  File "/usr/local/var/pyenv/versions/3.9.0/envs/venv3.9.0/lib/python3.9/site-packages/django/core/handlers/exception.py", line 55, in inner
    response = get_response(request)
  File "/usr/local/var/pyenv/versions/3.9.0/envs/venv3.9.0/lib/python3.9/site-packages/django/utils/deprecation.py", line 134, in __call__
    response = response or self.get_response(request)
  File "/usr/local/var/pyenv/versions/3.9.0/envs/venv3.9.0/lib/python3.9/site-packages/django/core/handlers/exception.py", line 57, in inner
    response = response_for_exception(request, exc)
  File "/usr/local/var/pyenv/versions/3.9.0/envs/venv3.9.0/lib/python3.9/site-packages/django/core/handlers/exception.py", line 140, in response_for_exception
    response = handle_uncaught_exception(
  File "/usr/local/var/pyenv/versions/3.9.0/envs/venv3.9.0/lib/python3.9/site-packages/django/core/handlers/exception.py", line 181, in handle_uncaught_exception
    return debug.technical_500_response(request, *exc_info)
  File "/usr/local/var/pyenv/versions/3.9.0/envs/venv3.9.0/lib/python3.9/site-packages/django/views/debug.py", line 67, in technical_500_response
    html = reporter.get_traceback_html()
  File "/usr/local/var/pyenv/versions/3.9.0/envs/venv3.9.0/lib/python3.9/site-packages/django/views/debug.py", line 410, in get_traceback_html
    c = Context(self.get_traceback_data(), use_l10n=False)
  File "/usr/local/var/pyenv/versions/3.9.0/envs/venv3.9.0/lib/python3.9/site-packages/django/views/debug.py", line 393, in get_traceback_data
    c["raising_view_name"] = get_caller(self.request)
  File "/usr/local/var/pyenv/versions/3.9.0/envs/venv3.9.0/lib/python3.9/site-packages/django/views/debug.py", line 100, in get_caller
    resolver_match = resolve(request.path)
  File "/usr/local/var/pyenv/versions/3.9.0/envs/venv3.9.0/lib/python3.9/site-packages/django/urls/base.py", line 24, in resolve
    return get_resolver(urlconf).resolve(path)
  File "/usr/local/var/pyenv/versions/3.9.0/envs/venv3.9.0/lib/python3.9/site-packages/django/urls/resolvers.py", line 663, in resolve
    for pattern in self.url_patterns:
  File "/usr/local/var/pyenv/versions/3.9.0/envs/venv3.9.0/lib/python3.9/site-packages/django/utils/functional.py", line 57, in __get__
    res = instance.__dict__[self.name] = self.func(instance)
  File "/usr/local/var/pyenv/versions/3.9.0/envs/venv3.9.0/lib/python3.9/site-packages/django/urls/resolvers.py", line 715, in url_patterns
    patterns = getattr(self.urlconf_module, "urlpatterns", self.urlconf_module)
  File "/usr/local/var/pyenv/versions/3.9.0/envs/venv3.9.0/lib/python3.9/site-packages/django/utils/functional.py", line 57, in __get__
    res = instance.__dict__[self.name] = self.func(instance)
  File "/usr/local/var/pyenv/versions/3.9.0/envs/venv3.9.0/lib/python3.9/site-packages/django/urls/resolvers.py", line 708, in urlconf_module
    return import_module(self.urlconf_name)
  File "/usr/local/var/pyenv/versions/3.9.0/lib/python3.9/importlib/__init__.py", line 127, in import_module
    return _bootstrap._gcd_import(name[level:], package, level)
  File "<frozen importlib._bootstrap>", line 1030, in _gcd_import
  File "<frozen importlib._bootstrap>", line 1007, in _find_and_load
  File "<frozen importlib._bootstrap>", line 986, in _find_and_load_unlocked
  File "<frozen importlib._bootstrap>", line 680, in _load_unlocked
  File "<frozen importlib._bootstrap_external>", line 790, in exec_module
  File "<frozen importlib._bootstrap>", line 228, in _call_with_frames_removed
  File "./backend/urls.py", line 17, in <module>
    from django.conf.static import serve
ModuleNotFoundError: No module named 'django.conf.static'

During handling of the above exception, another exception occurred:

Traceback (most recent call last):
  File "/usr/local/var/pyenv/versions/3.9.0/envs/venv3.9.0/lib/python3.9/site-packages/django/core/handlers/exception.py", line 55, in inner
    response = get_response(request)
  File "/usr/local/var/pyenv/versions/3.9.0/envs/venv3.9.0/lib/python3.9/site-packages/django/utils/deprecation.py", line 134, in __call__
    response = response or self.get_response(request)
  File "/usr/local/var/pyenv/versions/3.9.0/envs/venv3.9.0/lib/python3.9/site-packages/django/core/handlers/exception.py", line 57, in inner
    response = response_for_exception(request, exc)
  File "/usr/local/var/pyenv/versions/3.9.0/envs/venv3.9.0/lib/python3.9/site-packages/django/core/handlers/exception.py", line 140, in response_for_exception
    response = handle_uncaught_exception(
  File "/usr/local/var/pyenv/versions/3.9.0/envs/venv3.9.0/lib/python3.9/site-packages/django/core/handlers/exception.py", line 181, in handle_uncaught_exception
    return debug.technical_500_response(request, *exc_info)
  File "/usr/local/var/pyenv/versions/3.9.0/envs/venv3.9.0/lib/python3.9/site-packages/django/views/debug.py", line 67, in technical_500_response
    html = reporter.get_traceback_html()
  File "/usr/local/var/pyenv/versions/3.9.0/envs/venv3.9.0/lib/python3.9/site-packages/django/views/debug.py", line 410, in get_traceback_html
    c = Context(self.get_traceback_data(), use_l10n=False)
  File "/usr/local/var/pyenv/versions/3.9.0/envs/venv3.9.0/lib/python3.9/site-packages/django/views/debug.py", line 393, in get_traceback_data
    c["raising_view_name"] = get_caller(self.request)
  File "/usr/local/var/pyenv/versions/3.9.0/envs/venv3.9.0/lib/python3.9/site-packages/django/views/debug.py", line 100, in get_caller
    resolver_match = resolve(request.path)
  File "/usr/local/var/pyenv/versions/3.9.0/envs/venv3.9.0/lib/python3.9/site-packages/django/urls/base.py", line 24, in resolve
    return get_resolver(urlconf).resolve(path)
  File "/usr/local/var/pyenv/versions/3.9.0/envs/venv3.9.0/lib/python3.9/site-packages/django/urls/resolvers.py", line 663, in resolve
    for pattern in self.url_patterns:
  File "/usr/local/var/pyenv/versions/3.9.0/envs/venv3.9.0/lib/python3.9/site-packages/django/utils/functional.py", line 57, in __get__
    res = instance.__dict__[self.name] = self.func(instance)
  File "/usr/local/var/pyenv/versions/3.9.0/envs/venv3.9.0/lib/python3.9/site-packages/django/urls/resolvers.py", line 715, in url_patterns
    patterns = getattr(self.urlconf_module, "urlpatterns", self.urlconf_module)
  File "/usr/local/var/pyenv/versions/3.9.0/envs/venv3.9.0/lib/python3.9/site-packages/django/utils/functional.py", line 57, in __get__
    res = instance.__dict__[self.name] = self.func(instance)
  File "/usr/local/var/pyenv/versions/3.9.0/envs/venv3.9.0/lib/python3.9/site-packages/django/urls/resolvers.py", line 708, in urlconf_module
    return import_module(self.urlconf_name)
  File "/usr/local/var/pyenv/versions/3.9.0/lib/python3.9/importlib/__init__.py", line 127, in import_module
    return _bootstrap._gcd_import(name[level:], package, level)
  File "<frozen importlib._bootstrap>", line 1030, in _gcd_import
  File "<frozen importlib._bootstrap>", line 1007, in _find_and_load
  File "<frozen importlib._bootstrap>", line 986, in _find_and_load_unlocked
  File "<frozen importlib._bootstrap>", line 680, in _load_unlocked
  File "<frozen importlib._bootstrap_external>", line 790, in exec_module
  File "<frozen importlib._bootstrap>", line 228, in _call_with_frames_removed
  File "./backend/urls.py", line 17, in <module>
    from django.conf.static import serve
ModuleNotFoundError: No module named 'django.conf.static'

During handling of the above exception, another exception occurred:

Traceback (most recent call last):
  File "/usr/local/var/pyenv/versions/3.9.0/envs/venv3.9.0/lib/python3.9/site-packages/django/core/handlers/exception.py", line 55, in inner
    response = get_response(request)
  File "/usr/local/var/pyenv/versions/3.9.0/envs/venv3.9.0/lib/python3.9/site-packages/django/utils/deprecation.py", line 134, in __call__
    response = response or self.get_response(request)
  File "/usr/local/var/pyenv/versions/3.9.0/envs/venv3.9.0/lib/python3.9/site-packages/django/core/handlers/exception.py", line 57, in inner
    response = response_for_exception(request, exc)
  File "/usr/local/var/pyenv/versions/3.9.0/envs/venv3.9.0/lib/python3.9/site-packages/django/core/handlers/exception.py", line 140, in response_for_exception
    response = handle_uncaught_exception(
  File "/usr/local/var/pyenv/versions/3.9.0/envs/venv3.9.0/lib/python3.9/site-packages/django/core/handlers/exception.py", line 181, in handle_uncaught_exception
    return debug.technical_500_response(request, *exc_info)
  File "/usr/local/var/pyenv/versions/3.9.0/envs/venv3.9.0/lib/python3.9/site-packages/django/views/debug.py", line 67, in technical_500_response
    html = reporter.get_traceback_html()
  File "/usr/local/var/pyenv/versions/3.9.0/envs/venv3.9.0/lib/python3.9/site-packages/django/views/debug.py", line 410, in get_traceback_html
    c = Context(self.get_traceback_data(), use_l10n=False)
  File "/usr/local/var/pyenv/versions/3.9.0/envs/venv3.9.0/lib/python3.9/site-packages/django/views/debug.py", line 393, in get_traceback_data
    c["raising_view_name"] = get_caller(self.request)
  File "/usr/local/var/pyenv/versions/3.9.0/envs/venv3.9.0/lib/python3.9/site-packages/django/views/debug.py", line 100, in get_caller
    resolver_match = resolve(request.path)
  File "/usr/local/var/pyenv/versions/3.9.0/envs/venv3.9.0/lib/python3.9/site-packages/django/urls/base.py", line 24, in resolve
    return get_resolver(urlconf).resolve(path)
  File "/usr/local/var/pyenv/versions/3.9.0/envs/venv3.9.0/lib/python3.9/site-packages/django/urls/resolvers.py", line 663, in resolve
    for pattern in self.url_patterns:
  File "/usr/local/var/pyenv/versions/3.9.0/envs/venv3.9.0/lib/python3.9/site-packages/django/utils/functional.py", line 57, in __get__
    res = instance.__dict__[self.name] = self.func(instance)
  File "/usr/local/var/pyenv/versions/3.9.0/envs/venv3.9.0/lib/python3.9/site-packages/django/urls/resolvers.py", line 715, in url_patterns
    patterns = getattr(self.urlconf_module, "urlpatterns", self.urlconf_module)
  File "/usr/local/var/pyenv/versions/3.9.0/envs/venv3.9.0/lib/python3.9/site-packages/django/utils/functional.py", line 57, in __get__
    res = instance.__dict__[self.name] = self.func(instance)
  File "/usr/local/var/pyenv/versions/3.9.0/envs/venv3.9.0/lib/python3.9/site-packages/django/urls/resolvers.py", line 708, in urlconf_module
    return import_module(self.urlconf_name)
  File "/usr/local/var/pyenv/versions/3.9.0/lib/python3.9/importlib/__init__.py", line 127, in import_module
    return _bootstrap._gcd_import(name[level:], package, level)
  File "<frozen importlib._bootstrap>", line 1030, in _gcd_import
  File "<frozen importlib._bootstrap>", line 1007, in _find_and_load
  File "<frozen importlib._bootstrap>", line 986, in _find_and_load_unlocked
  File "<frozen importlib._bootstrap>", line 680, in _load_unlocked
  File "<frozen importlib._bootstrap_external>", line 790, in exec_module
  File "<frozen importlib._bootstrap>", line 228, in _call_with_frames_removed
  File "./backend/urls.py", line 17, in <module>
    from django.conf.static import serve
ModuleNotFoundError: No module named 'django.conf.static'

During handling of the above exception, another exception occurred:

Traceback (most recent call last):
  File "/usr/local/var/pyenv/versions/3.9.0/envs/venv3.9.0/lib/python3.9/site-packages/django/core/handlers/exception.py", line 55, in inner
    response = get_response(request)
  File "/usr/local/var/pyenv/versions/3.9.0/envs/venv3.9.0/lib/python3.9/site-packages/django/utils/deprecation.py", line 134, in __call__
    response = response or self.get_response(request)
  File "/usr/local/var/pyenv/versions/3.9.0/envs/venv3.9.0/lib/python3.9/site-packages/django/core/handlers/exception.py", line 57, in inner
    response = response_for_exception(request, exc)
  File "/usr/local/var/pyenv/versions/3.9.0/envs/venv3.9.0/lib/python3.9/site-packages/django/core/handlers/exception.py", line 140, in response_for_exception
    response = handle_uncaught_exception(
  File "/usr/local/var/pyenv/versions/3.9.0/envs/venv3.9.0/lib/python3.9/site-packages/django/core/handlers/exception.py", line 181, in handle_uncaught_exception
    return debug.technical_500_response(request, *exc_info)
  File "/usr/local/var/pyenv/versions/3.9.0/envs/venv3.9.0/lib/python3.9/site-packages/django/views/debug.py", line 67, in technical_500_response
    html = reporter.get_traceback_html()
  File "/usr/local/var/pyenv/versions/3.9.0/envs/venv3.9.0/lib/python3.9/site-packages/django/views/debug.py", line 410, in get_traceback_html
    c = Context(self.get_traceback_data(), use_l10n=False)
  File "/usr/local/var/pyenv/versions/3.9.0/envs/venv3.9.0/lib/python3.9/site-packages/django/views/debug.py", line 393, in get_traceback_data
    c["raising_view_name"] = get_caller(self.request)
  File "/usr/local/var/pyenv/versions/3.9.0/envs/venv3.9.0/lib/python3.9/site-packages/django/views/debug.py", line 100, in get_caller
    resolver_match = resolve(request.path)
  File "/usr/local/var/pyenv/versions/3.9.0/envs/venv3.9.0/lib/python3.9/site-packages/django/urls/base.py", line 24, in resolve
    return get_resolver(urlconf).resolve(path)
  File "/usr/local/var/pyenv/versions/3.9.0/envs/venv3.9.0/lib/python3.9/site-packages/django/urls/resolvers.py", line 663, in resolve
    for pattern in self.url_patterns:
  File "/usr/local/var/pyenv/versions/3.9.0/envs/venv3.9.0/lib/python3.9/site-packages/django/utils/functional.py", line 57, in __get__
    res = instance.__dict__[self.name] = self.func(instance)
  File "/usr/local/var/pyenv/versions/3.9.0/envs/venv3.9.0/lib/python3.9/site-packages/django/urls/resolvers.py", line 715, in url_patterns
    patterns = getattr(self.urlconf_module, "urlpatterns", self.urlconf_module)
  File "/usr/local/var/pyenv/versions/3.9.0/envs/venv3.9.0/lib/python3.9/site-packages/django/utils/functional.py", line 57, in __get__
    res = instance.__dict__[self.name] = self.func(instance)
  File "/usr/local/var/pyenv/versions/3.9.0/envs/venv3.9.0/lib/python3.9/site-packages/django/urls/resolvers.py", line 708, in urlconf_module
    return import_module(self.urlconf_name)
  File "/usr/local/var/pyenv/versions/3.9.0/lib/python3.9/importlib/__init__.py", line 127, in import_module
    return _bootstrap._gcd_import(name[level:], package, level)
  File "<frozen importlib._bootstrap>", line 1030, in _gcd_import
  File "<frozen importlib._bootstrap>", line 1007, in _find_and_load
  File "<frozen importlib._bootstrap>", line 986, in _find_and_load_unlocked
  File "<frozen importlib._bootstrap>", line 680, in _load_unlocked
  File "<frozen importlib._bootstrap_external>", line 790, in exec_module
  File "<frozen importlib._bootstrap>", line 228, in _call_with_frames_removed
  File "./backend/urls.py", line 17, in <module>
    from django.conf.static import serve
ModuleNotFoundError: No module named 'django.conf.static'

During handling of the above exception, another exception occurred:

Traceback (most recent call last):
  File "/usr/local/var/pyenv/versions/3.9.0/envs/venv3.9.0/lib/python3.9/site-packages/django/core/handlers/wsgi.py", line 124, in __call__
    response = self.get_response(request)
  File "/usr/local/var/pyenv/versions/3.9.0/envs/venv3.9.0/lib/python3.9/site-packages/django/core/handlers/base.py", line 140, in get_response
    response = self._middleware_chain(request)
  File "/usr/local/var/pyenv/versions/3.9.0/envs/venv3.9.0/lib/python3.9/site-packages/django/core/handlers/exception.py", line 57, in inner
    response = response_for_exception(request, exc)
  File "/usr/local/var/pyenv/versions/3.9.0/envs/venv3.9.0/lib/python3.9/site-packages/django/core/handlers/exception.py", line 140, in response_for_exception
    response = handle_uncaught_exception(
  File "/usr/local/var/pyenv/versions/3.9.0/envs/venv3.9.0/lib/python3.9/site-packages/django/core/handlers/exception.py", line 181, in handle_uncaught_exception
    return debug.technical_500_response(request, *exc_info)
  File "/usr/local/var/pyenv/versions/3.9.0/envs/venv3.9.0/lib/python3.9/site-packages/django/views/debug.py", line 67, in technical_500_response
    html = reporter.get_traceback_html()
  File "/usr/local/var/pyenv/versions/3.9.0/envs/venv3.9.0/lib/python3.9/site-packages/django/views/debug.py", line 410, in get_traceback_html
    c = Context(self.get_traceback_data(), use_l10n=False)
  File "/usr/local/var/pyenv/versions/3.9.0/envs/venv3.9.0/lib/python3.9/site-packages/django/views/debug.py", line 393, in get_traceback_data
    c["raising_view_name"] = get_caller(self.request)
  File "/usr/local/var/pyenv/versions/3.9.0/envs/venv3.9.0/lib/python3.9/site-packages/django/views/debug.py", line 100, in get_caller
    resolver_match = resolve(request.path)
  File "/usr/local/var/pyenv/versions/3.9.0/envs/venv3.9.0/lib/python3.9/site-packages/django/urls/base.py", line 24, in resolve
    return get_resolver(urlconf).resolve(path)
  File "/usr/local/var/pyenv/versions/3.9.0/envs/venv3.9.0/lib/python3.9/site-packages/django/urls/resolvers.py", line 663, in resolve
    for pattern in self.url_patterns:
  File "/usr/local/var/pyenv/versions/3.9.0/envs/venv3.9.0/lib/python3.9/site-packages/django/utils/functional.py", line 57, in __get__
    res = instance.__dict__[self.name] = self.func(instance)
  File "/usr/local/var/pyenv/versions/3.9.0/envs/venv3.9.0/lib/python3.9/site-packages/django/urls/resolvers.py", line 715, in url_patterns
    patterns = getattr(self.urlconf_module, "urlpatterns", self.urlconf_module)
  File "/usr/local/var/pyenv/versions/3.9.0/envs/venv3.9.0/lib/python3.9/site-packages/django/utils/functional.py", line 57, in __get__
    res = instance.__dict__[self.name] = self.func(instance)
  File "/usr/local/var/pyenv/versions/3.9.0/envs/venv3.9.0/lib/python3.9/site-packages/django/urls/resolvers.py", line 708, in urlconf_module
    return import_module(self.urlconf_name)
  File "/usr/local/var/pyenv/versions/3.9.0/lib/python3.9/importlib/__init__.py", line 127, in import_module
    return _bootstrap._gcd_import(name[level:], package, level)
  File "<frozen importlib._bootstrap>", line 1030, in _gcd_import
  File "<frozen importlib._bootstrap>", line 1007, in _find_and_load
  File "<frozen importlib._bootstrap>", line 986, in _find_and_load_unlocked
  File "<frozen importlib._bootstrap>", line 680, in _load_unlocked
  File "<frozen importlib._bootstrap_external>", line 790, in exec_module
  File "<frozen importlib._bootstrap>", line 228, in _call_with_frames_removed
  File "./backend/urls.py", line 17, in <module>
    from django.conf.static import serve
ModuleNotFoundError: No module named 'django.conf.static'
[pid: 85342|app: 0|req: 1/18] 127.0.0.1 () {58 vars in 1313 bytes} [Tue Jul  4 07:55:00 2023] GET /static/images/04877dc43746a4e2498ece93540c48aa.png => generated 0 bytes in 2100 msecs (HTTP/1.1 500) 0 headers in 0 bytes (0 switches on core 1)
gateway "uWSGI http 1" has been buried (pid: 85345)
...brutally killing workers...
worker 4 buried after 1 seconds
worker 3 buried after 1 seconds
worker 2 buried after 1 seconds
worker 1 buried after 1 seconds
binary reloading uWSGI...
chdir() to /Users/lvjing/sorcery-management-platform/backend
closing all non-uwsgi socket fds > 2 (max_fd = 10240)...
found fd 3 mapped to socket 0 (127.0.0.1:64093)
running /usr/local/var/pyenv/versions/3.9.0/envs/venv3.9.0/bin/uwsgi
[uWSGI] getting INI configuration from uwsgi.ini
*** Starting uWSGI 2.0.21 (64bit) on [Tue Jul  4 07:57:08 2023] ***
compiled with version: Apple LLVM 14.0.3 (clang-1403.0.22.14.1) on 04 July 2023 07:43:37
os: Darwin-22.5.0 Darwin Kernel Version 22.5.0: Thu Jun  8 22:22:22 PDT 2023; root:xnu-8796.121.3~7/RELEASE_X86_64
nodename: lvjingdeMacBook-Pro.local
machine: x86_64
clock source: unix
pcre jit disabled
detected number of CPU cores: 12
current working directory: /Users/lvjing/sorcery-management-platform/backend
detected binary path: /usr/local/var/pyenv/versions/3.9.0/envs/venv3.9.0/bin/uwsgi
chdir() to /Users/lvjing/sorcery-management-platform/backend
your processes number limit is 2784
your memory page size is 4096 bytes
detected max file descriptor number: 10240
lock engine: OSX spinlocks
thunder lock: disabled (you can enable it with --thunder-lock)
uWSGI http bound on 0.0.0.0:8000 fd 5
uwsgi socket 0 bound to TCP address 127.0.0.1:51480 (port auto-assigned) fd 4
Python version: 3.9.0 (default, Jun  6 2023, 10:09:24)  [Clang 14.0.3 (clang-1403.0.22.14.1)]
Python main interpreter initialized at 0x7fa73f0040d0
python threads support enabled
your server socket listen backlog is limited to 100 connections
your mercy for graceful operations on workers is 60 seconds
mapped 416640 bytes (406 KB) for 8 cores
*** Operational MODE: preforking+threaded ***
WSGI app 0 (mountpoint='') ready in 1 seconds on interpreter 0x7fa73f0040d0 pid: 85316 (default app)
*** uWSGI is running in multiple interpreter mode ***
gracefully (RE)spawned uWSGI master process (pid: 85316)
spawned uWSGI worker 1 (pid: 90065, cores: 2)
spawned uWSGI worker 2 (pid: 90066, cores: 2)
spawned uWSGI worker 3 (pid: 90067, cores: 2)
spawned uWSGI worker 4 (pid: 90068, cores: 2)
spawned uWSGI http 1 (pid: 90069)
*** Starting uWSGI 2.0.21 (64bit) on [Tue Jul  4 16:12:30 2023] ***
compiled with version: Apple LLVM 14.0.3 (clang-1403.0.22.14.1) on 04 July 2023 07:43:37
os: Darwin-22.5.0 Darwin Kernel Version 22.5.0: Thu Jun  8 22:22:22 PDT 2023; root:xnu-8796.121.3~7/RELEASE_X86_64
nodename: lvjingdeMacBook-Pro.local
machine: x86_64
clock source: unix
pcre jit disabled
detected number of CPU cores: 12
current working directory: /Users/lvjing/sorcery-management-platform/backend
writing pidfile to uwsgi.pid
detected binary path: /usr/local/var/pyenv/versions/3.9.0/envs/venv3.9.0/bin/uwsgi
chdir() to /Users/lvjing/sorcery-management-platform/backend
your processes number limit is 2784
your memory page size is 4096 bytes
detected max file descriptor number: 10240
lock engine: OSX spinlocks
thunder lock: disabled (you can enable it with --thunder-lock)
probably another instance of uWSGI is running on the same address (0.0.0.0:8000).
bind(): Address already in use [core/socket.c line 769]
ERROR (2003, "Can't connect to MySQL server on '127.0.0.1' ([Errno 61] Connection refused)")
Traceback (most recent call last):
  File "/usr/local/var/pyenv/versions/3.9.0/envs/venv3.9.0/lib/python3.9/site-packages/pymysql/connections.py", line 616, in connect
    sock = socket.create_connection(
  File "/usr/local/var/pyenv/versions/3.9.0/lib/python3.9/socket.py", line 843, in create_connection
    raise err
  File "/usr/local/var/pyenv/versions/3.9.0/lib/python3.9/socket.py", line 831, in create_connection
    sock.connect(sa)
ConnectionRefusedError: [Errno 61] Connection refused

During handling of the above exception, another exception occurred:

Traceback (most recent call last):
  File "/usr/local/var/pyenv/versions/3.9.0/envs/venv3.9.0/lib/python3.9/site-packages/django/db/backends/base/base.py", line 289, in ensure_connection
    self.connect()
  File "/usr/local/var/pyenv/versions/3.9.0/envs/venv3.9.0/lib/python3.9/site-packages/django/utils/asyncio.py", line 26, in inner
    return func(*args, **kwargs)
  File "/usr/local/var/pyenv/versions/3.9.0/envs/venv3.9.0/lib/python3.9/site-packages/django/db/backends/base/base.py", line 270, in connect
    self.connection = self.get_new_connection(conn_params)
  File "/usr/local/var/pyenv/versions/3.9.0/envs/venv3.9.0/lib/python3.9/site-packages/django/utils/asyncio.py", line 26, in inner
    return func(*args, **kwargs)
  File "/usr/local/var/pyenv/versions/3.9.0/envs/venv3.9.0/lib/python3.9/site-packages/django/db/backends/mysql/base.py", line 247, in get_new_connection
    connection = Database.connect(**conn_params)
  File "/usr/local/var/pyenv/versions/3.9.0/envs/venv3.9.0/lib/python3.9/site-packages/pymysql/connections.py", line 352, in __init__
    self.connect()
  File "/usr/local/var/pyenv/versions/3.9.0/envs/venv3.9.0/lib/python3.9/site-packages/pymysql/connections.py", line 668, in connect
    raise exc
pymysql.err.OperationalError: (2003, "Can't connect to MySQL server on '127.0.0.1' ([Errno 61] Connection refused)")

The above exception was the direct cause of the following exception:

Traceback (most recent call last):
  File "/usr/local/var/pyenv/versions/3.9.0/envs/venv3.9.0/lib/python3.9/site-packages/ninja/operation.py", line 150, in _run_authentication
    result = callback(request)
  File "/usr/local/var/pyenv/versions/3.9.0/envs/venv3.9.0/lib/python3.9/site-packages/ninja/security/http.py", line 39, in __call__
    return self.authenticate(request, token)
  File "./backend/api.py", line 38, in authenticate
    Session.objects.get(pk=token)
  File "/usr/local/var/pyenv/versions/3.9.0/envs/venv3.9.0/lib/python3.9/site-packages/django/db/models/manager.py", line 87, in manager_method
    return getattr(self.get_queryset(), name)(*args, **kwargs)
  File "/usr/local/var/pyenv/versions/3.9.0/envs/venv3.9.0/lib/python3.9/site-packages/django/db/models/query.py", line 633, in get
    num = len(clone)
  File "/usr/local/var/pyenv/versions/3.9.0/envs/venv3.9.0/lib/python3.9/site-packages/django/db/models/query.py", line 380, in __len__
    self._fetch_all()
  File "/usr/local/var/pyenv/versions/3.9.0/envs/venv3.9.0/lib/python3.9/site-packages/django/db/models/query.py", line 1881, in _fetch_all
    self._result_cache = list(self._iterable_class(self))
  File "/usr/local/var/pyenv/versions/3.9.0/envs/venv3.9.0/lib/python3.9/site-packages/django/db/models/query.py", line 91, in __iter__
    results = compiler.execute_sql(
  File "/usr/local/var/pyenv/versions/3.9.0/envs/venv3.9.0/lib/python3.9/site-packages/django/db/models/sql/compiler.py", line 1560, in execute_sql
    cursor = self.connection.cursor()
  File "/usr/local/var/pyenv/versions/3.9.0/envs/venv3.9.0/lib/python3.9/site-packages/django/utils/asyncio.py", line 26, in inner
    return func(*args, **kwargs)
  File "/usr/local/var/pyenv/versions/3.9.0/envs/venv3.9.0/lib/python3.9/site-packages/django/db/backends/base/base.py", line 330, in cursor
    return self._cursor()
  File "/usr/local/var/pyenv/versions/3.9.0/envs/venv3.9.0/lib/python3.9/site-packages/django/db/backends/base/base.py", line 306, in _cursor
    self.ensure_connection()
  File "/usr/local/var/pyenv/versions/3.9.0/envs/venv3.9.0/lib/python3.9/site-packages/django/utils/asyncio.py", line 26, in inner
    return func(*args, **kwargs)
  File "/usr/local/var/pyenv/versions/3.9.0/envs/venv3.9.0/lib/python3.9/site-packages/django/db/backends/base/base.py", line 289, in ensure_connection
    self.connect()
  File "/usr/local/var/pyenv/versions/3.9.0/envs/venv3.9.0/lib/python3.9/site-packages/django/db/utils.py", line 91, in __exit__
    raise dj_exc_value.with_traceback(traceback) from exc_value
  File "/usr/local/var/pyenv/versions/3.9.0/envs/venv3.9.0/lib/python3.9/site-packages/django/db/backends/base/base.py", line 289, in ensure_connection
    self.connect()
  File "/usr/local/var/pyenv/versions/3.9.0/envs/venv3.9.0/lib/python3.9/site-packages/django/utils/asyncio.py", line 26, in inner
    return func(*args, **kwargs)
  File "/usr/local/var/pyenv/versions/3.9.0/envs/venv3.9.0/lib/python3.9/site-packages/django/db/backends/base/base.py", line 270, in connect
    self.connection = self.get_new_connection(conn_params)
  File "/usr/local/var/pyenv/versions/3.9.0/envs/venv3.9.0/lib/python3.9/site-packages/django/utils/asyncio.py", line 26, in inner
    return func(*args, **kwargs)
  File "/usr/local/var/pyenv/versions/3.9.0/envs/venv3.9.0/lib/python3.9/site-packages/django/db/backends/mysql/base.py", line 247, in get_new_connection
    connection = Database.connect(**conn_params)
  File "/usr/local/var/pyenv/versions/3.9.0/envs/venv3.9.0/lib/python3.9/site-packages/pymysql/connections.py", line 352, in __init__
    self.connect()
  File "/usr/local/var/pyenv/versions/3.9.0/envs/venv3.9.0/lib/python3.9/site-packages/pymysql/connections.py", line 668, in connect
    raise exc
django.db.utils.OperationalError: (2003, "Can't connect to MySQL server on '127.0.0.1' ([Errno 61] Connection refused)")
ERROR Internal Server Error: /api/users/info
[pid: 90067|app: 0|req: 1/1] 127.0.0.1 () {60 vars in 1268 bytes} [Tue Jul  4 08:12:54 2023] GET /api/users/info => generated 5891 bytes in 935 msecs (HTTP/1.1 500) 6 headers in 213 bytes (2 switches on core 0)
ERROR (2003, "Can't connect to MySQL server on '127.0.0.1' ([Errno 61] Connection refused)")
Traceback (most recent call last):
  File "/usr/local/var/pyenv/versions/3.9.0/envs/venv3.9.0/lib/python3.9/site-packages/pymysql/connections.py", line 616, in connect
    sock = socket.create_connection(
  File "/usr/local/var/pyenv/versions/3.9.0/lib/python3.9/socket.py", line 843, in create_connection
    raise err
  File "/usr/local/var/pyenv/versions/3.9.0/lib/python3.9/socket.py", line 831, in create_connection
    sock.connect(sa)
ConnectionRefusedError: [Errno 61] Connection refused

During handling of the above exception, another exception occurred:

Traceback (most recent call last):
  File "/usr/local/var/pyenv/versions/3.9.0/envs/venv3.9.0/lib/python3.9/site-packages/django/db/backends/base/base.py", line 289, in ensure_connection
    self.connect()
  File "/usr/local/var/pyenv/versions/3.9.0/envs/venv3.9.0/lib/python3.9/site-packages/django/utils/asyncio.py", line 26, in inner
    return func(*args, **kwargs)
  File "/usr/local/var/pyenv/versions/3.9.0/envs/venv3.9.0/lib/python3.9/site-packages/django/db/backends/base/base.py", line 270, in connect
    self.connection = self.get_new_connection(conn_params)
  File "/usr/local/var/pyenv/versions/3.9.0/envs/venv3.9.0/lib/python3.9/site-packages/django/utils/asyncio.py", line 26, in inner
    return func(*args, **kwargs)
  File "/usr/local/var/pyenv/versions/3.9.0/envs/venv3.9.0/lib/python3.9/site-packages/django/db/backends/mysql/base.py", line 247, in get_new_connection
    connection = Database.connect(**conn_params)
  File "/usr/local/var/pyenv/versions/3.9.0/envs/venv3.9.0/lib/python3.9/site-packages/pymysql/connections.py", line 352, in __init__
    self.connect()
  File "/usr/local/var/pyenv/versions/3.9.0/envs/venv3.9.0/lib/python3.9/site-packages/pymysql/connections.py", line 668, in connect
    raise exc
pymysql.err.OperationalError: (2003, "Can't connect to MySQL server on '127.0.0.1' ([Errno 61] Connection refused)")

The above exception was the direct cause of the following exception:

Traceback (most recent call last):
  File "/usr/local/var/pyenv/versions/3.9.0/envs/venv3.9.0/lib/python3.9/site-packages/ninja/operation.py", line 104, in run
    result = self.view_func(request, **values)
  File "./users/api.py", line 51, in user_login
    user = auth.authenticate(username=username, password=password)
  File "/usr/local/var/pyenv/versions/3.9.0/envs/venv3.9.0/lib/python3.9/site-packages/django/views/decorators/debug.py", line 42, in sensitive_variables_wrapper
    return func(*func_args, **func_kwargs)
  File "/usr/local/var/pyenv/versions/3.9.0/envs/venv3.9.0/lib/python3.9/site-packages/django/contrib/auth/__init__.py", line 77, in authenticate
    user = backend.authenticate(request, **credentials)
  File "/usr/local/var/pyenv/versions/3.9.0/envs/venv3.9.0/lib/python3.9/site-packages/django/contrib/auth/backends.py", line 46, in authenticate
    user = UserModel._default_manager.get_by_natural_key(username)
  File "/usr/local/var/pyenv/versions/3.9.0/envs/venv3.9.0/lib/python3.9/site-packages/django/contrib/auth/base_user.py", line 54, in get_by_natural_key
    return self.get(**{self.model.USERNAME_FIELD: username})
  File "/usr/local/var/pyenv/versions/3.9.0/envs/venv3.9.0/lib/python3.9/site-packages/django/db/models/manager.py", line 87, in manager_method
    return getattr(self.get_queryset(), name)(*args, **kwargs)
  File "/usr/local/var/pyenv/versions/3.9.0/envs/venv3.9.0/lib/python3.9/site-packages/django/db/models/query.py", line 633, in get
    num = len(clone)
  File "/usr/local/var/pyenv/versions/3.9.0/envs/venv3.9.0/lib/python3.9/site-packages/django/db/models/query.py", line 380, in __len__
    self._fetch_all()
  File "/usr/local/var/pyenv/versions/3.9.0/envs/venv3.9.0/lib/python3.9/site-packages/django/db/models/query.py", line 1881, in _fetch_all
    self._result_cache = list(self._iterable_class(self))
  File "/usr/local/var/pyenv/versions/3.9.0/envs/venv3.9.0/lib/python3.9/site-packages/django/db/models/query.py", line 91, in __iter__
    results = compiler.execute_sql(
  File "/usr/local/var/pyenv/versions/3.9.0/envs/venv3.9.0/lib/python3.9/site-packages/django/db/models/sql/compiler.py", line 1560, in execute_sql
    cursor = self.connection.cursor()
  File "/usr/local/var/pyenv/versions/3.9.0/envs/venv3.9.0/lib/python3.9/site-packages/django/utils/asyncio.py", line 26, in inner
    return func(*args, **kwargs)
  File "/usr/local/var/pyenv/versions/3.9.0/envs/venv3.9.0/lib/python3.9/site-packages/django/db/backends/base/base.py", line 330, in cursor
    return self._cursor()
  File "/usr/local/var/pyenv/versions/3.9.0/envs/venv3.9.0/lib/python3.9/site-packages/django/db/backends/base/base.py", line 306, in _cursor
    self.ensure_connection()
  File "/usr/local/var/pyenv/versions/3.9.0/envs/venv3.9.0/lib/python3.9/site-packages/django/utils/asyncio.py", line 26, in inner
    return func(*args, **kwargs)
  File "/usr/local/var/pyenv/versions/3.9.0/envs/venv3.9.0/lib/python3.9/site-packages/django/db/backends/base/base.py", line 289, in ensure_connection
    self.connect()
  File "/usr/local/var/pyenv/versions/3.9.0/envs/venv3.9.0/lib/python3.9/site-packages/django/db/utils.py", line 91, in __exit__
    raise dj_exc_value.with_traceback(traceback) from exc_value
  File "/usr/local/var/pyenv/versions/3.9.0/envs/venv3.9.0/lib/python3.9/site-packages/django/db/backends/base/base.py", line 289, in ensure_connection
    self.connect()
  File "/usr/local/var/pyenv/versions/3.9.0/envs/venv3.9.0/lib/python3.9/site-packages/django/utils/asyncio.py", line 26, in inner
    return func(*args, **kwargs)
  File "/usr/local/var/pyenv/versions/3.9.0/envs/venv3.9.0/lib/python3.9/site-packages/django/db/backends/base/base.py", line 270, in connect
    self.connection = self.get_new_connection(conn_params)
  File "/usr/local/var/pyenv/versions/3.9.0/envs/venv3.9.0/lib/python3.9/site-packages/django/utils/asyncio.py", line 26, in inner
    return func(*args, **kwargs)
  File "/usr/local/var/pyenv/versions/3.9.0/envs/venv3.9.0/lib/python3.9/site-packages/django/db/backends/mysql/base.py", line 247, in get_new_connection
    connection = Database.connect(**conn_params)
  File "/usr/local/var/pyenv/versions/3.9.0/envs/venv3.9.0/lib/python3.9/site-packages/pymysql/connections.py", line 352, in __init__
    self.connect()
  File "/usr/local/var/pyenv/versions/3.9.0/envs/venv3.9.0/lib/python3.9/site-packages/pymysql/connections.py", line 668, in connect
    raise exc
django.db.utils.OperationalError: (2003, "Can't connect to MySQL server on '127.0.0.1' ([Errno 61] Connection refused)")
ERROR Internal Server Error: /api/users/login
[pid: 90068|app: 0|req: 1/2] 127.0.0.1 () {66 vars in 1277 bytes} [Tue Jul  4 08:12:57 2023] POST /api/users/login => generated 6576 bytes in 666 msecs (HTTP/1.1 500) 6 headers in 213 bytes (1 switches on core 0)
[pid: 90067|app: 0|req: 2/3] 127.0.0.1 () {66 vars in 1277 bytes} [Tue Jul  4 08:13:37 2023] POST /api/users/login => generated 142 bytes in 360 msecs (HTTP/1.1 200) 9 headers in 509 bytes (1 switches on core 1)
[pid: 90067|app: 0|req: 3/4] 127.0.0.1 () {60 vars in 1268 bytes} [Tue Jul  4 08:13:38 2023] GET /api/users/info => generated 118 bytes in 16 msecs (HTTP/1.1 200) 7 headers in 228 bytes (1 switches on core 0)
[pid: 90068|app: 0|req: 2/5] 127.0.0.1 () {60 vars in 1315 bytes} [Tue Jul  4 08:13:40 2023] GET /api/httprunner/projects?page=1&size=10 => generated 558 bytes in 41 msecs (HTTP/1.1 200) 6 headers in 214 bytes (2 switches on core 1)
[pid: 90067|app: 0|req: 4/6] 127.0.0.1 () {66 vars in 1407 bytes} [Tue Jul  4 08:13:42 2023] POST /api/projects/list?page=1&size=6 => generated 1240 bytes in 18 msecs (HTTP/1.1 200) 6 headers in 215 bytes (2 switches on core 1)
WARNING Not Found: /static/images/105131d433a807eb1c778be9c93286f1.png
[pid: 90068|app: 0|req: 3/7] 127.0.0.1 () {58 vars in 1313 bytes} [Tue Jul  4 08:13:42 2023] GET /static/images/105131d433a807eb1c778be9c93286f1.png => generated 2332 bytes in 15 msecs (HTTP/1.1 404) 6 headers in 215 bytes (1 switches on core 0)
WARNING Not Found: /static/images/04877dc43746a4e2498ece93540c48aa.png
[pid: 90066|app: 0|req: 1/8] 127.0.0.1 () {58 vars in 1313 bytes} [Tue Jul  4 08:13:42 2023] GET /static/images/04877dc43746a4e2498ece93540c48aa.png => generated 2332 bytes in 800 msecs (HTTP/1.1 404) 6 headers in 215 bytes (1 switches on core 1)
[pid: 90068|app: 0|req: 4/9] 127.0.0.1 () {64 vars in 1321 bytes} [Tue Jul  4 08:13:53 2023] GET /api/users/info => generated 118 bytes in 22 msecs (HTTP/1.1 200) 7 headers in 228 bytes (2 switches on core 1)
WARNING Not Found: /static/images/rose.png
[pid: 90067|app: 0|req: 5/10] 127.0.0.1 () {62 vars in 1355 bytes} [Tue Jul  4 08:13:53 2023] GET /static/images/rose.png?imageView2/1/w/80/h/80 => generated 2271 bytes in 17 msecs (HTTP/1.1 404) 6 headers in 215 bytes (1 switches on core 0)
[pid: 90068|app: 0|req: 5/11] 127.0.0.1 () {70 vars in 1460 bytes} [Tue Jul  4 08:13:53 2023] POST /api/projects/list?page=1&size=6 => generated 1240 bytes in 32 msecs (HTTP/1.1 200) 6 headers in 215 bytes (1 switches on core 0)
WARNING Not Found: /static/images/105131d433a807eb1c778be9c93286f1.png
[pid: 90067|app: 0|req: 6/12] 127.0.0.1 () {62 vars in 1366 bytes} [Tue Jul  4 08:13:53 2023] GET /static/images/105131d433a807eb1c778be9c93286f1.png => generated 2332 bytes in 11 msecs (HTTP/1.1 404) 6 headers in 215 bytes (2 switches on core 1)
WARNING Not Found: /static/images/5dde59cf0979a4b0000d4b4c8c33f9d1.png
[pid: 90068|app: 0|req: 7/13] 127.0.0.1 () {62 vars in 1366 bytes} [Tue Jul  4 08:13:53 2023] GET /static/images/5dde59cf0979a4b0000d4b4c8c33f9d1.png => generated 2332 bytes in 19 msecs (HTTP/1.1 404) 6 headers in 215 bytes (1 switches on core 1)
WARNING Not Found: /static/images/04877dc43746a4e2498ece93540c48aa.png
[pid: 90068|app: 0|req: 7/14] 127.0.0.1 () {62 vars in 1364 bytes} [Tue Jul  4 08:13:53 2023] GET /static/images/04877dc43746a4e2498ece93540c48aa.png => generated 2332 bytes in 20 msecs (HTTP/1.1 404) 6 headers in 215 bytes (2 switches on core 0)
gateway "uWSGI http 1" has been buried (pid: 90069)
...brutally killing workers...
worker 4 buried after 1 seconds
worker 3 buried after 1 seconds
worker 2 buried after 1 seconds
worker 1 buried after 1 seconds
binary reloading uWSGI...
chdir() to /Users/lvjing/sorcery-management-platform/backend
closing all non-uwsgi socket fds > 2 (max_fd = 10240)...
found fd 4 mapped to socket 0 (127.0.0.1:51480)
running /usr/local/var/pyenv/versions/3.9.0/envs/venv3.9.0/bin/uwsgi
[uWSGI] getting INI configuration from uwsgi.ini
*** Starting uWSGI 2.0.21 (64bit) on [Tue Jul  4 08:51:16 2023] ***
compiled with version: Apple LLVM 14.0.3 (clang-1403.0.22.14.1) on 04 July 2023 07:43:37
os: Darwin-22.5.0 Darwin Kernel Version 22.5.0: Thu Jun  8 22:22:22 PDT 2023; root:xnu-8796.121.3~7/RELEASE_X86_64
nodename: lvjingdeMacBook-Pro.local
machine: x86_64
clock source: unix
pcre jit disabled
detected number of CPU cores: 12
current working directory: /Users/lvjing/sorcery-management-platform/backend
detected binary path: /usr/local/var/pyenv/versions/3.9.0/envs/venv3.9.0/bin/uwsgi
chdir() to /Users/lvjing/sorcery-management-platform/backend
your processes number limit is 2784
your memory page size is 4096 bytes
detected max file descriptor number: 10240
lock engine: OSX spinlocks
thunder lock: disabled (you can enable it with --thunder-lock)
uWSGI http bound on 0.0.0.0:8000 fd 5
uwsgi socket 0 bound to TCP address 127.0.0.1:60743 (port auto-assigned) fd 3
Python version: 3.9.0 (default, Jun  6 2023, 10:09:24)  [Clang 14.0.3 (clang-1403.0.22.14.1)]
Python main interpreter initialized at 0x7fe8dd7042e0
python threads support enabled
your server socket listen backlog is limited to 100 connections
your mercy for graceful operations on workers is 60 seconds
mapped 416640 bytes (406 KB) for 8 cores
*** Operational MODE: preforking+threaded ***
WSGI app 0 (mountpoint='') ready in 1 seconds on interpreter 0x7fe8dd7042e0 pid: 85316 (default app)
*** uWSGI is running in multiple interpreter mode ***
gracefully (RE)spawned uWSGI master process (pid: 85316)
spawned uWSGI worker 1 (pid: 9759, cores: 2)
spawned uWSGI worker 2 (pid: 9760, cores: 2)
spawned uWSGI worker 3 (pid: 9761, cores: 2)
spawned uWSGI worker 4 (pid: 9762, cores: 2)
spawned uWSGI http 1 (pid: 9763)
[pid: 9761|app: 0|req: 1/1] 127.0.0.1 () {60 vars in 1268 bytes} [Tue Jul  4 08:51:25 2023] GET /api/users/info => generated 143 bytes in 777 msecs (HTTP/1.1 400) 4 headers in 172 bytes (1 switches on core 0)
[pid: 9762|app: 0|req: 1/2] 127.0.0.1 () {66 vars in 1277 bytes} [Tue Jul  4 08:51:30 2023] POST /api/users/login => generated 143 bytes in 483 msecs (HTTP/1.1 400) 4 headers in 172 bytes (1 switches on core 1)
[pid: 9761|app: 0|req: 2/3] 127.0.0.1 () {66 vars in 1277 bytes} [Tue Jul  4 08:52:24 2023] POST /api/users/login => generated 143 bytes in 2 msecs (HTTP/1.1 400) 4 headers in 172 bytes (2 switches on core 1)
[pid: 9760|app: 0|req: 1/4] 127.0.0.1 () {70 vars in 1329 bytes} [Tue Jul  4 08:52:53 2023] POST /api/users/login => generated 143 bytes in 719 msecs (HTTP/1.1 400) 4 headers in 172 bytes (2 switches on core 0)
[pid: 9762|app: 0|req: 2/5] 127.0.0.1 () {70 vars in 1330 bytes} [Tue Jul  4 08:53:24 2023] POST /api/users/login => generated 143 bytes in 13 msecs (HTTP/1.1 400) 4 headers in 172 bytes (1 switches on core 0)
[pid: 9762|app: 0|req: 3/6] 127.0.0.1 () {70 vars in 1330 bytes} [Tue Jul  4 08:53:52 2023] POST /api/users/login => generated 143 bytes in 3 msecs (HTTP/1.1 400) 4 headers in 172 bytes (1 switches on core 1)
[pid: 9761|app: 0|req: 3/7] 127.0.0.1 () {70 vars in 1330 bytes} [Tue Jul  4 08:53:53 2023] POST /api/users/login => generated 143 bytes in 7 msecs (HTTP/1.1 400) 4 headers in 172 bytes (2 switches on core 1)
respawned uWSGI http 1 (pid: 11365)
DAMN ! worker 4 (pid: 9762) died, killed by signal 9 :( trying respawn ...
Respawned uWSGI worker 4 (new pid: 11426)
DAMN ! worker 3 (pid: 9761) died, killed by signal 9 :( trying respawn ...
Respawned uWSGI worker 3 (new pid: 11474)
DAMN ! worker 2 (pid: 9760) died, killed by signal 9 :( trying respawn ...
Respawned uWSGI worker 2 (new pid: 11520)
DAMN ! worker 1 (pid: 9759) died, killed by signal 9 :( trying respawn ...
Respawned uWSGI worker 1 (new pid: 11586)
Tue Jul  4 08:54:48 2023 - uWSGI worker 2 screams: UAAAAAAH my master disconnected: i will kill myself !!!
Tue Jul  4 08:54:48 2023 - uWSGI worker 1 screams: UAAAAAAH my master disconnected: i will kill myself !!!
Tue Jul  4 08:54:48 2023 - uWSGI worker 4 screams: UAAAAAAH my master disconnected: i will kill myself !!!
Tue Jul  4 08:54:48 2023 - uWSGI worker 3 screams: UAAAAAAH my master disconnected: i will kill myself !!!
Tue Jul  4 08:54:48 2023 - uWSGI worker 1 screams: UAAAAAAH my master disconnected: i will kill myself !!!
Tue Jul  4 08:54:48 2023 - uWSGI worker 2 screams: UAAAAAAH my master disconnected: i will kill myself !!!
Tue Jul  4 08:54:48 2023 - uWSGI worker 4 screams: UAAAAAAH my master disconnected: i will kill myself !!!
Tue Jul  4 08:54:48 2023 - uWSGI worker 3 screams: UAAAAAAH my master disconnected: i will kill myself !!!
*** Starting uWSGI 2.0.21 (64bit) on [Tue Jul  4 16:55:24 2023] ***
compiled with version: Apple LLVM 14.0.3 (clang-1403.0.22.14.1) on 04 July 2023 07:43:37
os: Darwin-22.5.0 Darwin Kernel Version 22.5.0: Thu Jun  8 22:22:22 PDT 2023; root:xnu-8796.121.3~7/RELEASE_X86_64
nodename: lvjingdeMacBook-Pro.local
machine: x86_64
clock source: unix
pcre jit disabled
detected number of CPU cores: 12
current working directory: /Users/lvjing/sorcery-management-platform/backend
writing pidfile to uwsgi.pid
detected binary path: /usr/local/var/pyenv/versions/3.9.0/envs/venv3.9.0/bin/uwsgi
chdir() to /Users/lvjing/sorcery-management-platform/backend
your processes number limit is 2784
your memory page size is 4096 bytes
detected max file descriptor number: 10240
lock engine: OSX spinlocks
thunder lock: disabled (you can enable it with --thunder-lock)
uWSGI http bound on 0.0.0.0:8000 fd 4
uwsgi socket 0 bound to TCP address 127.0.0.1:61666 (port auto-assigned) fd 3
Python version: 3.9.0 (default, Jun  6 2023, 10:09:24)  [Clang 14.0.3 (clang-1403.0.22.14.1)]
Python main interpreter initialized at 0x7fc9573060b0
python threads support enabled
your server socket listen backlog is limited to 100 connections
your mercy for graceful operations on workers is 60 seconds
mapped 218688 bytes (213 KB) for 2 cores
*** Operational MODE: preforking ***
WSGI app 0 (mountpoint='') ready in 0 seconds on interpreter 0x7fc9573060b0 pid: 11988 (default app)
*** uWSGI is running in multiple interpreter mode ***
spawned uWSGI master process (pid: 11988)
spawned uWSGI worker 1 (pid: 12011, cores: 1)
spawned uWSGI worker 2 (pid: 12012, cores: 1)
spawned uWSGI http 1 (pid: 12013)
[pid: 12012|app: 0|req: 1/1] 127.0.0.1 () {70 vars in 1329 bytes} [Tue Jul  4 08:55:39 2023] POST /api/users/login => generated 143 bytes in 690 msecs (HTTP/1.1 400) 4 headers in 172 bytes (1 switches on core 0)
respawned uWSGI http 1 (pid: 13499)
DAMN ! worker 2 (pid: 12012) died, killed by signal 9 :( trying respawn ...
Respawned uWSGI worker 2 (new pid: 13540)
DAMN ! worker 1 (pid: 12011) died, killed by signal 9 :( trying respawn ...
Respawned uWSGI worker 1 (new pid: 13612)
Tue Jul  4 08:59:14 2023 - uWSGI worker 1 screams: UAAAAAAH my master disconnected: i will kill myself !!!
Tue Jul  4 08:59:14 2023 - uWSGI worker 2 screams: UAAAAAAH my master disconnected: i will kill myself !!!
*** Starting uWSGI 2.0.21 (64bit) on [Tue Jul  4 16:59:28 2023] ***
compiled with version: Apple LLVM 14.0.3 (clang-1403.0.22.14.1) on 04 July 2023 07:43:37
os: Darwin-22.5.0 Darwin Kernel Version 22.5.0: Thu Jun  8 22:22:22 PDT 2023; root:xnu-8796.121.3~7/RELEASE_X86_64
nodename: lvjingdeMacBook-Pro.local
machine: x86_64
clock source: unix
pcre jit disabled
detected number of CPU cores: 12
current working directory: /Users/lvjing/sorcery-management-platform/backend
writing pidfile to uwsgi.pid
detected binary path: /usr/local/var/pyenv/versions/3.9.0/envs/venv3.9.0/bin/uwsgi
chdir() to /Users/lvjing/sorcery-management-platform/backend
your processes number limit is 2784
your memory page size is 4096 bytes
detected max file descriptor number: 10240
lock engine: OSX spinlocks
thunder lock: disabled (you can enable it with --thunder-lock)
uWSGI http bound on 0.0.0.0:8000 fd 4
uwsgi socket 0 bound to TCP address 127.0.0.1:63025 (port auto-assigned) fd 3
Python version: 3.9.0 (default, Jun  6 2023, 10:09:24)  [Clang 14.0.3 (clang-1403.0.22.14.1)]
Python main interpreter initialized at 0x7fcd63206f90
python threads support enabled
your server socket listen backlog is limited to 100 connections
your mercy for graceful operations on workers is 60 seconds
mapped 218688 bytes (213 KB) for 2 cores
*** Operational MODE: preforking ***
WSGI app 0 (mountpoint='') ready in 0 seconds on interpreter 0x7fcd63206f90 pid: 13844 (default app)
*** uWSGI is running in multiple interpreter mode ***
spawned uWSGI master process (pid: 13844)
spawned uWSGI worker 1 (pid: 13870, cores: 1)
spawned uWSGI worker 2 (pid: 13871, cores: 1)
spawned uWSGI http 1 (pid: 13872)
Traceback (most recent call last):
  File "/usr/local/var/pyenv/versions/3.9.0/envs/venv3.9.0/lib/python3.9/site-packages/django/core/handlers/exception.py", line 55, in inner
    response = get_response(request)
  File "/usr/local/var/pyenv/versions/3.9.0/envs/venv3.9.0/lib/python3.9/site-packages/django/utils/deprecation.py", line 133, in __call__
    response = self.process_request(request)
  File "/usr/local/var/pyenv/versions/3.9.0/envs/venv3.9.0/lib/python3.9/site-packages/django/middleware/common.py", line 48, in process_request
    host = request.get_host()
  File "/usr/local/var/pyenv/versions/3.9.0/envs/venv3.9.0/lib/python3.9/site-packages/django/http/request.py", line 150, in get_host
    raise DisallowedHost(msg)
django.core.exceptions.DisallowedHost: Invalid HTTP_HOST header: '127.0.0.1:8000'. You may need to add '127.0.0.1' to ALLOWED_HOSTS.

During handling of the above exception, another exception occurred:

Traceback (most recent call last):
  File "/usr/local/var/pyenv/versions/3.9.0/envs/venv3.9.0/lib/python3.9/site-packages/django/core/handlers/exception.py", line 163, in get_exception_response
    callback = resolver.resolve_error_handler(status_code)
  File "/usr/local/var/pyenv/versions/3.9.0/envs/venv3.9.0/lib/python3.9/site-packages/django/urls/resolvers.py", line 729, in resolve_error_handler
    callback = getattr(self.urlconf_module, "handler%s" % view_type, None)
  File "/usr/local/var/pyenv/versions/3.9.0/envs/venv3.9.0/lib/python3.9/site-packages/django/utils/functional.py", line 57, in __get__
    res = instance.__dict__[self.name] = self.func(instance)
  File "/usr/local/var/pyenv/versions/3.9.0/envs/venv3.9.0/lib/python3.9/site-packages/django/urls/resolvers.py", line 708, in urlconf_module
    return import_module(self.urlconf_name)
  File "/usr/local/var/pyenv/versions/3.9.0/lib/python3.9/importlib/__init__.py", line 127, in import_module
    return _bootstrap._gcd_import(name[level:], package, level)
  File "<frozen importlib._bootstrap>", line 1030, in _gcd_import
  File "<frozen importlib._bootstrap>", line 1007, in _find_and_load
  File "<frozen importlib._bootstrap>", line 986, in _find_and_load_unlocked
  File "<frozen importlib._bootstrap>", line 680, in _load_unlocked
  File "<frozen importlib._bootstrap_external>", line 790, in exec_module
  File "<frozen importlib._bootstrap>", line 228, in _call_with_frames_removed
  File "./backend/urls.py", line 17, in <module>
    from django.conf.static import serve
ModuleNotFoundError: No module named 'django.conf.static'

During handling of the above exception, another exception occurred:

Traceback (most recent call last):
  File "/usr/local/var/pyenv/versions/3.9.0/envs/venv3.9.0/lib/python3.9/site-packages/django/core/handlers/exception.py", line 55, in inner
    response = get_response(request)
  File "/usr/local/var/pyenv/versions/3.9.0/envs/venv3.9.0/lib/python3.9/site-packages/django/utils/deprecation.py", line 134, in __call__
    response = response or self.get_response(request)
  File "/usr/local/var/pyenv/versions/3.9.0/envs/venv3.9.0/lib/python3.9/site-packages/django/core/handlers/exception.py", line 57, in inner
    response = response_for_exception(request, exc)
  File "/usr/local/var/pyenv/versions/3.9.0/envs/venv3.9.0/lib/python3.9/site-packages/django/core/handlers/exception.py", line 134, in response_for_exception
    response = get_exception_response(
  File "/usr/local/var/pyenv/versions/3.9.0/envs/venv3.9.0/lib/python3.9/site-packages/django/core/handlers/exception.py", line 167, in get_exception_response
    response = handle_uncaught_exception(request, resolver, sys.exc_info())
  File "/usr/local/var/pyenv/versions/3.9.0/envs/venv3.9.0/lib/python3.9/site-packages/django/core/handlers/exception.py", line 184, in handle_uncaught_exception
    callback = resolver.resolve_error_handler(500)
  File "/usr/local/var/pyenv/versions/3.9.0/envs/venv3.9.0/lib/python3.9/site-packages/django/urls/resolvers.py", line 729, in resolve_error_handler
    callback = getattr(self.urlconf_module, "handler%s" % view_type, None)
  File "/usr/local/var/pyenv/versions/3.9.0/envs/venv3.9.0/lib/python3.9/site-packages/django/utils/functional.py", line 57, in __get__
    res = instance.__dict__[self.name] = self.func(instance)
  File "/usr/local/var/pyenv/versions/3.9.0/envs/venv3.9.0/lib/python3.9/site-packages/django/urls/resolvers.py", line 708, in urlconf_module
    return import_module(self.urlconf_name)
  File "/usr/local/var/pyenv/versions/3.9.0/lib/python3.9/importlib/__init__.py", line 127, in import_module
    return _bootstrap._gcd_import(name[level:], package, level)
  File "<frozen importlib._bootstrap>", line 1030, in _gcd_import
  File "<frozen importlib._bootstrap>", line 1007, in _find_and_load
  File "<frozen importlib._bootstrap>", line 986, in _find_and_load_unlocked
  File "<frozen importlib._bootstrap>", line 680, in _load_unlocked
  File "<frozen importlib._bootstrap_external>", line 790, in exec_module
  File "<frozen importlib._bootstrap>", line 228, in _call_with_frames_removed
  File "./backend/urls.py", line 17, in <module>
    from django.conf.static import serve
ModuleNotFoundError: No module named 'django.conf.static'

During handling of the above exception, another exception occurred:

Traceback (most recent call last):
  File "/usr/local/var/pyenv/versions/3.9.0/envs/venv3.9.0/lib/python3.9/site-packages/django/core/handlers/exception.py", line 55, in inner
    response = get_response(request)
  File "/usr/local/var/pyenv/versions/3.9.0/envs/venv3.9.0/lib/python3.9/site-packages/django/utils/deprecation.py", line 134, in __call__
    response = response or self.get_response(request)
  File "/usr/local/var/pyenv/versions/3.9.0/envs/venv3.9.0/lib/python3.9/site-packages/django/core/handlers/exception.py", line 57, in inner
    response = response_for_exception(request, exc)
  File "/usr/local/var/pyenv/versions/3.9.0/envs/venv3.9.0/lib/python3.9/site-packages/django/core/handlers/exception.py", line 140, in response_for_exception
    response = handle_uncaught_exception(
  File "/usr/local/var/pyenv/versions/3.9.0/envs/venv3.9.0/lib/python3.9/site-packages/django/core/handlers/exception.py", line 184, in handle_uncaught_exception
    callback = resolver.resolve_error_handler(500)
  File "/usr/local/var/pyenv/versions/3.9.0/envs/venv3.9.0/lib/python3.9/site-packages/django/urls/resolvers.py", line 729, in resolve_error_handler
    callback = getattr(self.urlconf_module, "handler%s" % view_type, None)
  File "/usr/local/var/pyenv/versions/3.9.0/envs/venv3.9.0/lib/python3.9/site-packages/django/utils/functional.py", line 57, in __get__
    res = instance.__dict__[self.name] = self.func(instance)
  File "/usr/local/var/pyenv/versions/3.9.0/envs/venv3.9.0/lib/python3.9/site-packages/django/urls/resolvers.py", line 708, in urlconf_module
    return import_module(self.urlconf_name)
  File "/usr/local/var/pyenv/versions/3.9.0/lib/python3.9/importlib/__init__.py", line 127, in import_module
    return _bootstrap._gcd_import(name[level:], package, level)
  File "<frozen importlib._bootstrap>", line 1030, in _gcd_import
  File "<frozen importlib._bootstrap>", line 1007, in _find_and_load
  File "<frozen importlib._bootstrap>", line 986, in _find_and_load_unlocked
  File "<frozen importlib._bootstrap>", line 680, in _load_unlocked
  File "<frozen importlib._bootstrap_external>", line 790, in exec_module
  File "<frozen importlib._bootstrap>", line 228, in _call_with_frames_removed
  File "./backend/urls.py", line 17, in <module>
    from django.conf.static import serve
ModuleNotFoundError: No module named 'django.conf.static'

During handling of the above exception, another exception occurred:

Traceback (most recent call last):
  File "/usr/local/var/pyenv/versions/3.9.0/envs/venv3.9.0/lib/python3.9/site-packages/django/core/handlers/wsgi.py", line 124, in __call__
    response = self.get_response(request)
  File "/usr/local/var/pyenv/versions/3.9.0/envs/venv3.9.0/lib/python3.9/site-packages/django/core/handlers/base.py", line 140, in get_response
    response = self._middleware_chain(request)
  File "/usr/local/var/pyenv/versions/3.9.0/envs/venv3.9.0/lib/python3.9/site-packages/django/core/handlers/exception.py", line 57, in inner
    response = response_for_exception(request, exc)
  File "/usr/local/var/pyenv/versions/3.9.0/envs/venv3.9.0/lib/python3.9/site-packages/django/core/handlers/exception.py", line 140, in response_for_exception
    response = handle_uncaught_exception(
  File "/usr/local/var/pyenv/versions/3.9.0/envs/venv3.9.0/lib/python3.9/site-packages/django/core/handlers/exception.py", line 184, in handle_uncaught_exception
    callback = resolver.resolve_error_handler(500)
  File "/usr/local/var/pyenv/versions/3.9.0/envs/venv3.9.0/lib/python3.9/site-packages/django/urls/resolvers.py", line 729, in resolve_error_handler
    callback = getattr(self.urlconf_module, "handler%s" % view_type, None)
  File "/usr/local/var/pyenv/versions/3.9.0/envs/venv3.9.0/lib/python3.9/site-packages/django/utils/functional.py", line 57, in __get__
    res = instance.__dict__[self.name] = self.func(instance)
  File "/usr/local/var/pyenv/versions/3.9.0/envs/venv3.9.0/lib/python3.9/site-packages/django/urls/resolvers.py", line 708, in urlconf_module
    return import_module(self.urlconf_name)
  File "/usr/local/var/pyenv/versions/3.9.0/lib/python3.9/importlib/__init__.py", line 127, in import_module
    return _bootstrap._gcd_import(name[level:], package, level)
  File "<frozen importlib._bootstrap>", line 1030, in _gcd_import
  File "<frozen importlib._bootstrap>", line 1007, in _find_and_load
  File "<frozen importlib._bootstrap>", line 986, in _find_and_load_unlocked
  File "<frozen importlib._bootstrap>", line 680, in _load_unlocked
  File "<frozen importlib._bootstrap_external>", line 790, in exec_module
  File "<frozen importlib._bootstrap>", line 228, in _call_with_frames_removed
  File "./backend/urls.py", line 17, in <module>
    from django.conf.static import serve
ModuleNotFoundError: No module named 'django.conf.static'
[pid: 13871|app: 0|req: 1/1] 127.0.0.1 () {70 vars in 1330 bytes} [Tue Jul  4 08:59:39 2023] POST /api/users/login => generated 0 bytes in 58 msecs (HTTP/1.1 500) 0 headers in 0 bytes (1 switches on core 0)
respawned uWSGI http 1 (pid: 15071)
DAMN ! worker 2 (pid: 13871) died, killed by signal 9 :( trying respawn ...
Respawned uWSGI worker 2 (new pid: 15140)
DAMN ! worker 1 (pid: 13870) died, killed by signal 9 :( trying respawn ...
Respawned uWSGI worker 1 (new pid: 15204)
Tue Jul  4 09:02:38 2023 - uWSGI worker 1 screams: UAAAAAAH my master disconnected: i will kill myself !!!
Tue Jul  4 09:02:38 2023 - uWSGI worker 2 screams: UAAAAAAH my master disconnected: i will kill myself !!!
*** Starting uWSGI 2.0.21 (64bit) on [Tue Jul  4 17:02:53 2023] ***
compiled with version: Apple LLVM 14.0.3 (clang-1403.0.22.14.1) on 04 July 2023 07:43:37
os: Darwin-22.5.0 Darwin Kernel Version 22.5.0: Thu Jun  8 22:22:22 PDT 2023; root:xnu-8796.121.3~7/RELEASE_X86_64
nodename: lvjingdeMacBook-Pro.local
machine: x86_64
clock source: unix
pcre jit disabled
detected number of CPU cores: 12
current working directory: /Users/lvjing/sorcery-management-platform/backend
writing pidfile to uwsgi.pid
detected binary path: /usr/local/var/pyenv/versions/3.9.0/envs/venv3.9.0/bin/uwsgi
chdir() to /Users/lvjing/sorcery-management-platform/backend
your processes number limit is 2784
your memory page size is 4096 bytes
detected max file descriptor number: 10240
lock engine: OSX spinlocks
thunder lock: disabled (you can enable it with --thunder-lock)
uWSGI http bound on 0.0.0.0:8000 fd 4
uwsgi socket 0 bound to TCP address 127.0.0.1:63977 (port auto-assigned) fd 3
Python version: 3.9.0 (default, Jun  6 2023, 10:09:24)  [Clang 14.0.3 (clang-1403.0.22.14.1)]
Python main interpreter initialized at 0x7f9aaf406f90
python threads support enabled
your server socket listen backlog is limited to 100 connections
your mercy for graceful operations on workers is 60 seconds
mapped 218688 bytes (213 KB) for 2 cores
*** Operational MODE: preforking ***
WSGI app 0 (mountpoint='') ready in 1 seconds on interpreter 0x7f9aaf406f90 pid: 15436 (default app)
*** uWSGI is running in multiple interpreter mode ***
spawned uWSGI master process (pid: 15436)
spawned uWSGI worker 1 (pid: 15459, cores: 1)
spawned uWSGI worker 2 (pid: 15460, cores: 1)
spawned uWSGI http 1 (pid: 15461)
[pid: 15460|app: 0|req: 1/1] 127.0.0.1 () {70 vars in 1329 bytes} [Tue Jul  4 09:03:00 2023] POST /api/users/login => generated 143 bytes in 737 msecs (HTTP/1.1 400) 4 headers in 172 bytes (1 switches on core 0)
[pid: 15460|app: 0|req: 2/2] 127.0.0.1 () {70 vars in 1330 bytes} [Tue Jul  4 09:03:56 2023] POST /api/users/login => generated 143 bytes in 4 msecs (HTTP/1.1 400) 4 headers in 172 bytes (2 switches on core 0)
[pid: 15460|app: 0|req: 3/3] 127.0.0.1 () {70 vars in 1330 bytes} [Tue Jul  4 09:04:27 2023] POST /api/users/login => generated 143 bytes in 2 msecs (HTTP/1.1 400) 4 headers in 172 bytes (2 switches on core 0)
respawned uWSGI http 1 (pid: 17330)
DAMN ! worker 2 (pid: 15460) died, killed by signal 9 :( trying respawn ...
Respawned uWSGI worker 2 (new pid: 17376)
DAMN ! worker 1 (pid: 15459) died, killed by signal 9 :( trying respawn ...
Respawned uWSGI worker 1 (new pid: 17414)
Tue Jul  4 09:07:19 2023 - uWSGI worker 2 screams: UAAAAAAH my master disconnected: i will kill myself !!!
Tue Jul  4 09:07:19 2023 - uWSGI worker 1 screams: UAAAAAAH my master disconnected: i will kill myself !!!
*** Starting uWSGI 2.0.21 (64bit) on [Tue Jul  4 17:07:49 2023] ***
compiled with version: Apple LLVM 14.0.3 (clang-1403.0.22.14.1) on 04 July 2023 07:43:37
os: Darwin-22.5.0 Darwin Kernel Version 22.5.0: Thu Jun  8 22:22:22 PDT 2023; root:xnu-8796.121.3~7/RELEASE_X86_64
nodename: lvjingdeMacBook-Pro.local
machine: x86_64
clock source: unix
pcre jit disabled
detected number of CPU cores: 12
current working directory: /Users/lvjing/sorcery-management-platform/backend
writing pidfile to uwsgi.pid
detected binary path: /usr/local/var/pyenv/versions/3.9.0/envs/venv3.9.0/bin/uwsgi
chdir() to /Users/lvjing/sorcery-management-platform/backend
your processes number limit is 2784
your memory page size is 4096 bytes
detected max file descriptor number: 10240
lock engine: OSX spinlocks
thunder lock: disabled (you can enable it with --thunder-lock)
uWSGI http bound on 0.0.0.0:8000 fd 4
uwsgi socket 0 bound to TCP address 127.0.0.1:49228 (port auto-assigned) fd 3
Python version: 3.9.0 (default, Jun  6 2023, 10:09:24)  [Clang 14.0.3 (clang-1403.0.22.14.1)]
Python main interpreter initialized at 0x7fc8b6906ba0
python threads support enabled
your server socket listen backlog is limited to 100 connections
your mercy for graceful operations on workers is 60 seconds
mapped 218688 bytes (213 KB) for 2 cores
*** Operational MODE: preforking ***
WSGI app 0 (mountpoint='') ready in 1 seconds on interpreter 0x7fc8b6906ba0 pid: 17799 (default app)
*** uWSGI is running in multiple interpreter mode ***
spawned uWSGI master process (pid: 17799)
spawned uWSGI worker 1 (pid: 17822, cores: 1)
spawned uWSGI worker 2 (pid: 17823, cores: 1)
spawned uWSGI http 1 (pid: 17824)
[pid: 17823|app: 0|req: 1/1] 127.0.0.1 () {70 vars in 1330 bytes} [Tue Jul  4 09:07:57 2023] POST /api/users/login => generated 143 bytes in 788 msecs (HTTP/1.1 400) 4 headers in 172 bytes (1 switches on core 0)
[pid: 17823|app: 0|req: 2/2] 127.0.0.1 () {70 vars in 1330 bytes} [Tue Jul  4 09:09:02 2023] POST /api/users/login => generated 143 bytes in 3 msecs (HTTP/1.1 400) 4 headers in 172 bytes (2 switches on core 0)
respawned uWSGI http 1 (pid: 22401)
DAMN ! worker 2 (pid: 17823) died, killed by signal 9 :( trying respawn ...
Respawned uWSGI worker 2 (new pid: 22464)
DAMN ! worker 1 (pid: 17822) died, killed by signal 9 :( trying respawn ...
Respawned uWSGI worker 1 (new pid: 22531)
Tue Jul  4 09:26:36 2023 - uWSGI worker 2 screams: UAAAAAAH my master disconnected: i will kill myself !!!
Tue Jul  4 09:26:36 2023 - uWSGI worker 1 screams: UAAAAAAH my master disconnected: i will kill myself !!!
*** Starting uWSGI 2.0.21 (64bit) on [Tue Jul  4 17:26:49 2023] ***
compiled with version: Apple LLVM 14.0.3 (clang-1403.0.22.14.1) on 04 July 2023 07:43:37
os: Darwin-22.5.0 Darwin Kernel Version 22.5.0: Thu Jun  8 22:22:22 PDT 2023; root:xnu-8796.121.3~7/RELEASE_X86_64
nodename: lvjingdeMacBook-Pro.local
machine: x86_64
clock source: unix
pcre jit disabled
detected number of CPU cores: 12
current working directory: /Users/lvjing/sorcery-management-platform/backend
writing pidfile to uwsgi.pid
detected binary path: /usr/local/var/pyenv/versions/3.9.0/envs/venv3.9.0/bin/uwsgi
chdir() to /Users/lvjing/sorcery-management-platform/backend
your processes number limit is 2784
your memory page size is 4096 bytes
detected max file descriptor number: 10240
lock engine: OSX spinlocks
thunder lock: disabled (you can enable it with --thunder-lock)
uWSGI http bound on 0.0.0.0:8000 fd 4
uwsgi socket 0 bound to TCP address 127.0.0.1:53025 (port auto-assigned) fd 3
Python version: 3.9.0 (default, Jun  6 2023, 10:09:24)  [Clang 14.0.3 (clang-1403.0.22.14.1)]
Python main interpreter initialized at 0x7fdf6ab05200
python threads support enabled
your server socket listen backlog is limited to 100 connections
your mercy for graceful operations on workers is 60 seconds
mapped 218688 bytes (213 KB) for 2 cores
*** Operational MODE: preforking ***
WSGI app 0 (mountpoint='') ready in 0 seconds on interpreter 0x7fdf6ab05200 pid: 22763 (default app)
*** uWSGI is running in multiple interpreter mode ***
spawned uWSGI master process (pid: 22763)
spawned uWSGI worker 1 (pid: 22788, cores: 1)
spawned uWSGI worker 2 (pid: 22789, cores: 1)
spawned uWSGI http 1 (pid: 22790)
[pid: 22789|app: 0|req: 1/1] 127.0.0.1 () {70 vars in 1330 bytes} [Tue Jul  4 09:27:00 2023] POST /api/users/login => generated 142 bytes in 1137 msecs (HTTP/1.1 200) 9 headers in 509 bytes (2 switches on core 0)
[pid: 22789|app: 0|req: 2/2] 127.0.0.1 () {64 vars in 1321 bytes} [Tue Jul  4 09:27:01 2023] GET /api/users/info => generated 118 bytes in 23 msecs (HTTP/1.1 200) 7 headers in 228 bytes (2 switches on core 0)
[pid: 22789|app: 0|req: 3/3] 127.0.0.1 () {70 vars in 1460 bytes} [Tue Jul  4 09:27:01 2023] POST /api/projects/list?page=1&size=6 => generated 1240 bytes in 54 msecs (HTTP/1.1 200) 6 headers in 215 bytes (2 switches on core 0)
[pid: 22789|app: 0|req: 4/4] 127.0.0.1 () {62 vars in 1366 bytes} [Tue Jul  4 09:27:01 2023] GET /static/images/105131d433a807eb1c778be9c93286f1.png => generated 261825 bytes in 12 msecs via sendfile() (HTTP/1.1 200) 8 headers in 319 bytes (1 switches on core 0)
[pid: 22789|app: 0|req: 5/5] 127.0.0.1 () {62 vars in 1366 bytes} [Tue Jul  4 09:27:01 2023] GET /static/images/04877dc43746a4e2498ece93540c48aa.png => generated 22938 bytes in 1 msecs via sendfile() (HTTP/1.1 200) 8 headers in 318 bytes (0 switches on core 0)
[pid: 22789|app: 0|req: 6/6] 127.0.0.1 () {62 vars in 1366 bytes} [Tue Jul  4 09:27:01 2023] GET /static/images/5dde59cf0979a4b0000d4b4c8c33f9d1.png => generated 1671071 bytes in 7 msecs via sendfile() (HTTP/1.1 200) 8 headers in 320 bytes (2 switches on core 0)
[pid: 22788|app: 0|req: 1/7] 127.0.0.1 () {62 vars in 1355 bytes} [Tue Jul  4 09:27:01 2023] GET /static/images/rose.png?imageView2/1/w/80/h/80 => generated 4496 bytes in 544 msecs via sendfile() (HTTP/1.1 200) 8 headers in 289 bytes (0 switches on core 0)
[pid: 22788|app: 0|req: 2/8] 127.0.0.1 () {66 vars in 1392 bytes} [Tue Jul  4 09:28:06 2023] POST /api/projects/list?page=1&size=10 => generated 1241 bytes in 37 msecs (HTTP/1.1 200) 6 headers in 215 bytes (2 switches on core 0)
[pid: 22789|app: 0|req: 7/9] 127.0.0.1 () {60 vars in 1297 bytes} [Tue Jul  4 09:28:06 2023] GET /api/modules/tree?project_id=1 => generated 140 bytes in 24 msecs (HTTP/1.1 200) 6 headers in 214 bytes (2 switches on core 0)
[pid: 22789|app: 0|req: 8/10] 127.0.0.1 () {62 vars in 1306 bytes} [Tue Jul  4 09:28:08 2023] GET /api/apis/module/3 => generated 342 bytes in 27 msecs (HTTP/1.1 200) 6 headers in 214 bytes (2 switches on core 0)
[pid: 22789|app: 0|req: 9/11] 127.0.0.1 () {60 vars in 1297 bytes} [Tue Jul  4 09:28:10 2023] GET /api/modules/tree?project_id=2 => generated 227 bytes in 18 msecs (HTTP/1.1 200) 6 headers in 214 bytes (2 switches on core 0)
[pid: 22789|app: 0|req: 10/12] 127.0.0.1 () {62 vars in 1306 bytes} [Tue Jul  4 09:28:11 2023] GET /api/apis/module/1 => generated 342 bytes in 22 msecs (HTTP/1.1 200) 6 headers in 214 bytes (1 switches on core 0)
[pid: 22789|app: 0|req: 11/13] 127.0.0.1 () {62 vars in 1306 bytes} [Tue Jul  4 09:28:11 2023] GET /api/apis/module/2 => generated 1007 bytes in 35 msecs (HTTP/1.1 200) 6 headers in 215 bytes (2 switches on core 0)
[pid: 22789|app: 0|req: 12/14] 127.0.0.1 () {60 vars in 1315 bytes} [Tue Jul  4 09:28:14 2023] GET /api/httprunner/projects?page=1&size=10 => generated 558 bytes in 27 msecs (HTTP/1.1 200) 6 headers in 214 bytes (2 switches on core 0)
[pid: 22788|app: 0|req: 3/15] 127.0.0.1 () {60 vars in 1313 bytes} [Tue Jul  4 09:28:15 2023] GET /api/httprunner/projects?page=1&size=6 => generated 557 bytes in 27 msecs (HTTP/1.1 200) 6 headers in 214 bytes (1 switches on core 0)
[pid: 22789|app: 0|req: 13/16] 127.0.0.1 () {66 vars in 1404 bytes} [Tue Jul  4 09:28:15 2023] POST /api/httprunner/apis/list?page=1&size=6 => generated 601 bytes in 35 msecs (HTTP/1.1 200) 6 headers in 214 bytes (2 switches on core 0)
env: seres系统测试环境
[pid: 22789|app: 0|req: 14/17] 127.0.0.1 () {66 vars in 1392 bytes} [Tue Jul  4 09:28:20 2023] POST /api/projects/list?page=1&size=10 => generated 1241 bytes in 33 msecs (HTTP/1.1 200) 6 headers in 215 bytes (2 switches on core 0)
env: DCS UAT测试环境
[pid: 22788|app: 0|req: 4/18] 127.0.0.1 () {66 vars in 1399 bytes} [Tue Jul  4 09:28:20 2023] POST /api/env/list?page=1&size=10 => generated 720 bytes in 41 msecs (HTTP/1.1 200) 6 headers in 214 bytes (1 switches on core 0)
respawned uWSGI http 1 (pid: 24696)
DAMN ! worker 2 (pid: 22789) died, killed by signal 9 :( trying respawn ...
Respawned uWSGI worker 2 (new pid: 24766)
DAMN ! worker 1 (pid: 22788) died, killed by signal 9 :( trying respawn ...
Respawned uWSGI worker 1 (new pid: 24836)
Tue Jul  4 09:31:55 2023 - uWSGI worker 2 screams: UAAAAAAH my master disconnected: i will kill myself !!!
Tue Jul  4 09:31:55 2023 - uWSGI worker 1 screams: UAAAAAAH my master disconnected: i will kill myself !!!
*** Starting uWSGI 2.0.21 (64bit) on [Fri Jul  7 10:32:24 2023] ***
compiled with version: Apple LLVM 14.0.3 (clang-1403.0.22.14.1) on 04 July 2023 07:43:37
os: Darwin-22.5.0 Darwin Kernel Version 22.5.0: Thu Jun  8 22:22:22 PDT 2023; root:xnu-8796.121.3~7/RELEASE_X86_64
nodename: lvjingdeMacBook-Pro.local
machine: x86_64
clock source: unix
pcre jit disabled
detected number of CPU cores: 12
current working directory: /Users/lvjing/sorcery-management-platform/backend
writing pidfile to uwsgi.pid
detected binary path: /usr/local/var/pyenv/versions/3.9.0/envs/venv3.9.0/bin/uwsgi
chdir() to /Users/lvjing/sorcery-management-platform/backend
your processes number limit is 2784
your memory page size is 4096 bytes
detected max file descriptor number: 10240
lock engine: OSX spinlocks
thunder lock: disabled (you can enable it with --thunder-lock)
uWSGI http bound on 0.0.0.0:8000 fd 4
uwsgi socket 0 bound to TCP address 127.0.0.1:55776 (port auto-assigned) fd 3
Python version: 3.9.0 (default, Jun  6 2023, 10:09:24)  [Clang 14.0.3 (clang-1403.0.22.14.1)]
Python main interpreter initialized at 0x7f8227b06f90
python threads support enabled
your server socket listen backlog is limited to 100 connections
your mercy for graceful operations on workers is 60 seconds
mapped 218688 bytes (213 KB) for 2 cores
*** Operational MODE: preforking ***
WSGI app 0 (mountpoint='') ready in 1 seconds on interpreter 0x7f8227b06f90 pid: 99888 (default app)
*** uWSGI is running in multiple interpreter mode ***
spawned uWSGI master process (pid: 99888)
spawned uWSGI worker 1 (pid: 99917, cores: 1)
spawned uWSGI worker 2 (pid: 99918, cores: 1)
spawned uWSGI http 1 (pid: 99919)
[pid: 99918|app: 0|req: 1/1] 127.0.0.1 () {64 vars in 1321 bytes} [Fri Jul  7 02:32:52 2023] GET /api/users/info => generated 118 bytes in 887 msecs (HTTP/1.1 200) 7 headers in 236 bytes (2 switches on core 0)
[pid: 99918|app: 0|req: 2/2] 127.0.0.1 () {62 vars in 1355 bytes} [Fri Jul  7 02:32:54 2023] GET /static/images/rose.png?imageView2/1/w/80/h/80 => generated 4496 bytes in 10 msecs via sendfile() (HTTP/1.1 200) 9 headers in 303 bytes (0 switches on core 0)
[pid: 99918|app: 0|req: 3/3] 127.0.0.1 () {64 vars in 1366 bytes} [Fri Jul  7 02:32:54 2023] GET /api/httprunner/projects?page=1&size=6 => generated 555 bytes in 38 msecs (HTTP/1.1 200) 7 headers in 228 bytes (1 switches on core 0)
[pid: 99917|app: 0|req: 1/4] 127.0.0.1 () {70 vars in 1457 bytes} [Fri Jul  7 02:32:54 2023] POST /api/httprunner/apis/list?page=1&size=6 => generated 601 bytes in 544 msecs (HTTP/1.1 200) 9 headers in 320 bytes (1 switches on core 0)
[pid: 99918|app: 0|req: 4/5] 127.0.0.1 () {68 vars in 1383 bytes} [Fri Jul  7 02:33:14 2023] DELETE /api/users/logout => generated 69 bytes in 56 msecs (HTTP/1.1 200) 10 headers in 426 bytes (2 switches on core 0)
[pid: 99918|app: 0|req: 5/6] 127.0.0.1 () {70 vars in 1286 bytes} [Fri Jul  7 02:33:15 2023] POST /api/users/login => generated 142 bytes in 361 msecs (HTTP/1.1 200) 11 headers in 609 bytes (2 switches on core 0)
[pid: 99918|app: 0|req: 6/7] 127.0.0.1 () {64 vars in 1321 bytes} [Fri Jul  7 02:33:16 2023] GET /api/users/info => generated 118 bytes in 41 msecs (HTTP/1.1 200) 7 headers in 236 bytes (2 switches on core 0)
[pid: 99918|app: 0|req: 7/8] 127.0.0.1 () {62 vars in 1355 bytes} [Fri Jul  7 02:33:16 2023] GET /static/images/rose.png?imageView2/1/w/80/h/80 => generated 4496 bytes in 1 msecs via sendfile() (HTTP/1.1 200) 9 headers in 303 bytes (1 switches on core 0)
[pid: 99918|app: 0|req: 8/9] 127.0.0.1 () {64 vars in 1366 bytes} [Fri Jul  7 02:33:16 2023] GET /api/httprunner/projects?page=1&size=6 => generated 555 bytes in 28 msecs (HTTP/1.1 200) 7 headers in 228 bytes (2 switches on core 0)
[pid: 99917|app: 0|req: 2/10] 127.0.0.1 () {70 vars in 1457 bytes} [Fri Jul  7 02:33:16 2023] POST /api/httprunner/apis/list?page=1&size=6 => generated 601 bytes in 39 msecs (HTTP/1.1 200) 9 headers in 320 bytes (2 switches on core 0)
[pid: 99918|app: 0|req: 9/11] 127.0.0.1 () {64 vars in 1349 bytes} [Fri Jul  7 02:33:42 2023] GET /api/httprunner/apis/detail/1 => generated 925 bytes in 39 msecs (HTTP/1.1 200) 7 headers in 228 bytes (2 switches on core 0)
[pid: 99918|app: 0|req: 10/12] 127.0.0.1 () {70 vars in 1457 bytes} [Fri Jul  7 02:33:47 2023] POST /api/httprunner/apis/list?page=1&size=6 => generated 601 bytes in 37 msecs (HTTP/1.1 200) 9 headers in 320 bytes (2 switches on core 0)
respawned uWSGI http 1 (pid: 1193)
DAMN ! worker 2 (pid: 99918) died, killed by signal 9 :( trying respawn ...
Respawned uWSGI worker 2 (new pid: 1254)
DAMN ! worker 1 (pid: 99917) died, killed by signal 9 :( trying respawn ...
Respawned uWSGI worker 1 (new pid: 1284)
Fri Jul  7 02:34:23 2023 - uWSGI worker 1 screams: UAAAAAAH my master disconnected: i will kill myself !!!
Fri Jul  7 02:34:23 2023 - uWSGI worker 2 screams: UAAAAAAH my master disconnected: i will kill myself !!!
*** Starting uWSGI 2.0.21 (64bit) on [Fri Jul  7 10:34:59 2023] ***
compiled with version: Apple LLVM 14.0.3 (clang-1403.0.22.14.1) on 04 July 2023 07:43:37
os: Darwin-22.5.0 Darwin Kernel Version 22.5.0: Thu Jun  8 22:22:22 PDT 2023; root:xnu-8796.121.3~7/RELEASE_X86_64
nodename: lvjingdeMacBook-Pro.local
machine: x86_64
clock source: unix
pcre jit disabled
detected number of CPU cores: 12
current working directory: /Users/lvjing/sorcery-management-platform/backend
writing pidfile to uwsgi.pid
detected binary path: /usr/local/var/pyenv/versions/3.9.0/envs/venv3.9.0/bin/uwsgi
chdir() to /Users/lvjing/sorcery-management-platform/backend
your processes number limit is 2784
your memory page size is 4096 bytes
detected max file descriptor number: 10240
lock engine: OSX spinlocks
thunder lock: disabled (you can enable it with --thunder-lock)
uWSGI http bound on 0.0.0.0:8000 fd 4
uwsgi socket 0 bound to TCP address 127.0.0.1:56503 (port auto-assigned) fd 3
Python version: 3.9.0 (default, Jun  6 2023, 10:09:24)  [Clang 14.0.3 (clang-1403.0.22.14.1)]
Python main interpreter initialized at 0x7fa97f406f90
python threads support enabled
your server socket listen backlog is limited to 100 connections
your mercy for graceful operations on workers is 60 seconds
mapped 218688 bytes (213 KB) for 2 cores
*** Operational MODE: preforking ***
WSGI app 0 (mountpoint='') ready in 0 seconds on interpreter 0x7fa97f406f90 pid: 1682 (default app)
*** uWSGI is running in multiple interpreter mode ***
spawned uWSGI master process (pid: 1682)
spawned uWSGI worker 1 (pid: 1706, cores: 1)
spawned uWSGI worker 2 (pid: 1707, cores: 1)
spawned uWSGI http 1 (pid: 1708)
[pid: 1707|app: 0|req: 1/1] 127.0.0.1 () {64 vars in 1321 bytes} [Fri Jul  7 02:35:02 2023] GET /api/users/info => generated 36 bytes in 699 msecs (HTTP/1.1 401) 7 headers in 237 bytes (1 switches on core 0)
[pid: 1707|app: 0|req: 2/2] 127.0.0.1 () {70 vars in 1330 bytes} [Fri Jul  7 02:35:05 2023] POST /api/users/login => generated 142 bytes in 496 msecs (HTTP/1.1 200) 11 headers in 609 bytes (2 switches on core 0)
[pid: 1707|app: 0|req: 3/3] 127.0.0.1 () {64 vars in 1321 bytes} [Fri Jul  7 02:35:06 2023] GET /api/users/info => generated 118 bytes in 93 msecs (HTTP/1.1 200) 7 headers in 236 bytes (2 switches on core 0)
[pid: 1707|app: 0|req: 4/4] 127.0.0.1 () {62 vars in 1355 bytes} [Fri Jul  7 02:35:06 2023] GET /static/images/rose.png?imageView2/1/w/80/h/80 => generated 4496 bytes in 6 msecs via sendfile() (HTTP/1.1 200) 9 headers in 303 bytes (0 switches on core 0)
[pid: 1707|app: 0|req: 5/5] 127.0.0.1 () {70 vars in 1457 bytes} [Fri Jul  7 02:35:06 2023] POST /api/httprunner/apis/list?page=1&size=6 => generated 97 bytes in 92 msecs (HTTP/1.1 200) 9 headers in 319 bytes (1 switches on core 0)
[pid: 1706|app: 0|req: 1/6] 127.0.0.1 () {64 vars in 1366 bytes} [Fri Jul  7 02:35:06 2023] GET /api/httprunner/projects?page=1&size=6 => generated 97 bytes in 695 msecs (HTTP/1.1 200) 7 headers in 227 bytes (2 switches on core 0)
[pid: 1707|app: 0|req: 6/7] 127.0.0.1 () {70 vars in 1460 bytes} [Fri Jul  7 02:35:09 2023] POST /api/projects/list?page=1&size=6 => generated 483 bytes in 92 msecs (HTTP/1.1 200) 9 headers in 320 bytes (1 switches on core 0)
[pid: 1706|app: 0|req: 2/8] 127.0.0.1 () {62 vars in 1365 bytes} [Fri Jul  7 02:35:09 2023] GET /static/images/04877dc43746a4e2498ece93540c48aa.png => generated 22938 bytes in 5 msecs via sendfile() (HTTP/1.1 200) 9 headers in 332 bytes (0 switches on core 0)
[pid: 1707|app: 0|req: 7/9] 127.0.0.1 () {62 vars in 1365 bytes} [Fri Jul  7 02:35:09 2023] GET /static/images/0b91469227ee4d89a0c3b171bae8631e.png => generated 179 bytes in 20 msecs (HTTP/1.1 404) 7 headers in 228 bytes (2 switches on core 0)
[pid: 1707|app: 0|req: 8/10] 127.0.0.1 () {68 vars in 1379 bytes} [Fri Jul  7 02:35:36 2023] DELETE /api/projects/2 => generated 69 bytes in 142 msecs (HTTP/1.1 200) 9 headers in 319 bytes (2 switches on core 0)
[pid: 1707|app: 0|req: 9/11] 127.0.0.1 () {70 vars in 1460 bytes} [Fri Jul  7 02:35:37 2023] POST /api/projects/list?page=1&size=6 => generated 310 bytes in 106 msecs (HTTP/1.1 200) 9 headers in 320 bytes (2 switches on core 0)
[pid: 1707|app: 0|req: 10/12] 127.0.0.1 () {64 vars in 1321 bytes} [Fri Jul  7 02:35:53 2023] GET /api/users/info => generated 118 bytes in 106 msecs (HTTP/1.1 200) 7 headers in 236 bytes (2 switches on core 0)
[pid: 1707|app: 0|req: 11/13] 127.0.0.1 () {62 vars in 1355 bytes} [Fri Jul  7 02:35:53 2023] GET /static/images/rose.png?imageView2/1/w/80/h/80 => generated 4496 bytes in 1 msecs via sendfile() (HTTP/1.1 200) 9 headers in 303 bytes (1 switches on core 0)
[pid: 1707|app: 0|req: 12/14] 127.0.0.1 () {70 vars in 1460 bytes} [Fri Jul  7 02:35:53 2023] POST /api/projects/list?page=1&size=6 => generated 310 bytes in 121 msecs (HTTP/1.1 200) 9 headers in 320 bytes (2 switches on core 0)
[pid: 1707|app: 0|req: 13/15] 127.0.0.1 () {62 vars in 1366 bytes} [Fri Jul  7 02:35:53 2023] GET /static/images/04877dc43746a4e2498ece93540c48aa.png => generated 22938 bytes in 1 msecs via sendfile() (HTTP/1.1 200) 9 headers in 332 bytes (1 switches on core 0)
[pid: 1707|app: 0|req: 14/16] 127.0.0.1 () {64 vars in 1329 bytes} [Fri Jul  7 02:36:06 2023] DELETE /api/users/logout => generated 69 bytes in 114 msecs (HTTP/1.1 200) 10 headers in 426 bytes (1 switches on core 0)
[pid: 1707|app: 0|req: 15/17] 127.0.0.1 () {66 vars in 1233 bytes} [Fri Jul  7 02:36:07 2023] POST /api/users/login => generated 142 bytes in 495 msecs (HTTP/1.1 200) 11 headers in 609 bytes (2 switches on core 0)
[pid: 1707|app: 0|req: 16/18] 127.0.0.1 () {60 vars in 1268 bytes} [Fri Jul  7 02:36:08 2023] GET /api/users/info => generated 118 bytes in 190 msecs (HTTP/1.1 200) 7 headers in 236 bytes (2 switches on core 0)
[pid: 1707|app: 0|req: 17/19] 127.0.0.1 () {66 vars in 1407 bytes} [Fri Jul  7 02:36:08 2023] POST /api/projects/list?page=1&size=6 => generated 310 bytes in 104 msecs (HTTP/1.1 200) 9 headers in 320 bytes (1 switches on core 0)
[pid: 1707|app: 0|req: 18/20] 127.0.0.1 () {66 vars in 1392 bytes} [Fri Jul  7 02:36:15 2023] POST /api/projects/list?page=1&size=10 => generated 311 bytes in 108 msecs (HTTP/1.1 200) 9 headers in 320 bytes (2 switches on core 0)
[pid: 1707|app: 0|req: 19/21] 127.0.0.1 () {60 vars in 1297 bytes} [Fri Jul  7 02:36:15 2023] GET /api/modules/tree?project_id=1 => generated 147 bytes in 108 msecs (HTTP/1.1 200) 7 headers in 228 bytes (1 switches on core 0)
[pid: 1707|app: 0|req: 20/22] 127.0.0.1 () {64 vars in 1330 bytes} [Fri Jul  7 02:36:28 2023] DELETE /api/users/logout => generated 69 bytes in 126 msecs (HTTP/1.1 200) 10 headers in 426 bytes (2 switches on core 0)
respawned uWSGI http 1 (pid: 2641)
DAMN ! worker 2 (pid: 1707) died, killed by signal 9 :( trying respawn ...
Respawned uWSGI worker 2 (new pid: 2740)
DAMN ! worker 1 (pid: 1706) died, killed by signal 9 :( trying respawn ...
Respawned uWSGI worker 1 (new pid: 2772)
Fri Jul  7 02:37:14 2023 - uWSGI worker 1 screams: UAAAAAAH my master disconnected: i will kill myself !!!
Fri Jul  7 02:37:14 2023 - uWSGI worker 2 screams: UAAAAAAH my master disconnected: i will kill myself !!!
